<?xml version="1.0" ?>
<!-- =================================================================================== -->
<!-- |    This document was autogenerated by xacro from /home/jc/catkin_ws/src/ur5_description/urdf/ur5_description_URDF.xacro | -->
<!-- |    EDITING THIS FILE BY HAND IS NOT RECOMMENDED                                 | -->
<!-- =================================================================================== -->
<robot name="ur5">
    <material name="silver">
        <color rgba="0.700 0.700 0.700 1.000" />
    </material>
    <transmission name="base_joint_tran">
        <type>transmission_interface/SimpleTransmission</type>
        <joint name="base_joint">
            <hardwareInterface>hardware_interface/EffortJointInterface</hardwareInterface>
        </joint>
        <actuator name="base_joint_actr">
            <hardwareInterface>hardware_interface/EffortJointInterface</hardwareInterface>
            <mechanicalReduction>1</mechanicalReduction>
        </actuator>
    </transmission>
    <transmission name="shoulder_joint_tran">
        <type>transmission_interface/SimpleTransmission</type>
        <joint name="shoulder_joint">
            <hardwareInterface>hardware_interface/EffortJointInterface</hardwareInterface>
        </joint>
        <actuator name="shoulder_joint_actr">
            <hardwareInterface>hardware_interface/EffortJointInterface</hardwareInterface>
            <mechanicalReduction>1</mechanicalReduction>
        </actuator>
    </transmission>
    <transmission name="arm_joint_tran">
        <type>transmission_interface/SimpleTransmission</type>
        <joint name="arm_joint">
            <hardwareInterface>hardware_interface/EffortJointInterface</hardwareInterface>
        </joint>
        <actuator name="arm_joint_actr">
            <hardwareInterface>hardware_interface/EffortJointInterface</hardwareInterface>
            <mechanicalReduction>1</mechanicalReduction>
        </actuator>
    </transmission>
    <transmission name="forearm_joint_tran">
        <type>transmission_interface/SimpleTransmission</type>
        <joint name="forearm_joint">
            <hardwareInterface>hardware_interface/EffortJointInterface</hardwareInterface>
        </joint>
        <actuator name="forearm_joint_actr">
            <hardwareInterface>hardware_interface/EffortJointInterface</hardwareInterface>
            <mechanicalReduction>1</mechanicalReduction>
        </actuator>
    </transmission>
    <transmission name="wrist_joint_tran">
        <type>transmission_interface/SimpleTransmission</type>
        <joint name="wrist_joint">
            <hardwareInterface>hardware_interface/EffortJointInterface</hardwareInterface>
        </joint>
        <actuator name="wrist_joint_actr">
            <hardwareInterface>hardware_interface/EffortJointInterface</hardwareInterface>
            <mechanicalReduction>1</mechanicalReduction>
        </actuator>
    </transmission>
    <transmission name="suction_joint_tran">
        <type>transmission_interface/SimpleTransmission</type>
        <joint name="suction_joint">
            <hardwareInterface>hardware_interface/EffortJointInterface</hardwareInterface>
        </joint>
        <actuator name="suction_joint_actr">
            <hardwareInterface>hardware_interface/EffortJointInterface</hardwareInterface>
            <mechanicalReduction>1</mechanicalReduction>
        </actuator>
    </transmission>
    <gazebo>
        <plugin filename="libgazebo_ros_control.so" name="control" />
        <plugin name="gazebo_ros_control">
            <robotNamespace>/</robotNamespace>
        </plugin>
    </gazebo>
    <gazebo reference="base_link">
        <material>Gazebo/Silver</material>
        <mu1>0.2</mu1>
        <mu2>0.2</mu2>
        <selfCollide>true</selfCollide>
        <gravity>true</gravity>
    </gazebo>
    <gazebo reference="shoulder_1">
        <material>Gazebo/Silver</material>
        <mu1>0.2</mu1>
        <mu2>0.2</mu2>
        <selfCollide>true</selfCollide>
    </gazebo>
    <gazebo reference="arm_1">
        <material>Gazebo/Silver</material>
        <mu1>0.2</mu1>
        <mu2>0.2</mu2>
        <selfCollide>true</selfCollide>
    </gazebo>
    <gazebo reference="forearm_1">
        <material>Gazebo/Silver</material>
        <mu1>0.2</mu1>
        <mu2>0.2</mu2>
        <selfCollide>true</selfCollide>
    </gazebo>
    <gazebo reference="wrist_1">
        <material>Gazebo/Silver</material>
        <mu1>0.2</mu1>
        <mu2>0.2</mu2>
        <selfCollide>true</selfCollide>
    </gazebo>
    <gazebo reference="end_1">
        <material>Gazebo/Silver</material>
        <mu1>0.2</mu1>
        <mu2>0.2</mu2>
        <selfCollide>true</selfCollide>
    </gazebo>
    <gazebo reference="suction_1">
        <material>Gazebo/Silver</material>
        <mu1>0.2</mu1>
        <mu2>0.2</mu2>
        <selfCollide>true</selfCollide>
    </gazebo>
    <link name="base_link">
        <inertial>
            <origin rpy="0 0 0" xyz="-8.269719423545992e-05 0.0010857267036388984 0.06047682470875622" />
            <mass value="29.485735477923164" />
            <inertia ixx="0.024776" ixy="7e-06" ixz="-2.2e-05" iyy="0.028156" iyz="0.000408" izz="0.038965" />
        </inertial>
        <visual>
            <origin rpy="0 0 0" xyz="0 0 0" />
            <geometry>
                <mesh filename="package://ur5_description/meshes/base_link.stl" scale="0.001 0.001 0.001" />
            </geometry>
            <material name="silver" />
        </visual>
        <collision>
            <origin rpy="0 0 0" xyz="0 0 0" />
            <geometry>
                <mesh filename="package://ur5_description/meshes/base_link.stl" scale="0.001 0.001 0.001" />
            </geometry>
        </collision>
    </link>
    <link name="shoulder_1">
        <inertial>
            <origin rpy="0 0 0" xyz="-5.136379737825127e-07 -0.012893561064329193 0.08338921276398253" />
            <mass value="7.491767242063588" />
            <inertia ixx="0.113371" ixy="-0.0" ixz="0.0" iyy="0.100756" iyz="0.0014" izz="0.094339" />
        </inertial>
        <visual>
            <origin rpy="0 0 0" xyz="0.0 -0.0 -0.0993" />
            <geometry>
                <mesh filename="package://ur5_description/meshes/shoulder_1.stl" scale="0.001 0.001 0.001" />
            </geometry>
            <material name="silver" />
        </visual>
        <collision>
            <origin rpy="0 0 0" xyz="0.0 -0.0 -0.0993" />
            <geometry>
                <mesh filename="package://ur5_description/meshes/shoulder_1.stl" scale="0.001 0.001 0.001" />
            </geometry>
        </collision>
    </link>
    <link name="arm_1">
        <inertial>
            <origin rpy="0 0 0" xyz="-6.124271792012328e-08 -0.08240844330284518 0.21130484810557812" />
            <mass value="3.96604980819084" />
            <inertia ixx="3.314125" ixy="-0.0" ixz="-1e-06" iyy="3.291262" iyz="-0.00734" izz="0.144311" />
        </inertial>
        <visual>
            <origin rpy="0 0 0" xyz="0.0 0.0946 -0.1807" />
            <geometry>
                <mesh filename="package://ur5_description/meshes/arm_1.stl" scale="0.001 0.001 0.001" />
            </geometry>
            <material name="silver" />
        </visual>
        <collision>
            <origin rpy="0 0 0" xyz="0.0 0.0946 -0.1807" />
            <geometry>
                <mesh filename="package://ur5_description/meshes/arm_1.stl" scale="0.001 0.001 0.001" />
            </geometry>
        </collision>
    </link>
    <link name="forearm_1">
        <inertial>
            <origin rpy="0 0 0" xyz="2.586346781728835e-07 0.06359393788395254 0.24263670260699677" />
            <mass value="1.327241051156584" />
            <inertia ixx="1.267089" ixy="0.0" ixz="0.0" iyy="1.261071" iyz="-0.041708" izz="0.0347" />
        </inertial>
        <visual>
            <origin rpy="0 0 0" xyz="0.0 0.1126 -0.7934" />
            <geometry>
                <mesh filename="package://ur5_description/meshes/forearm_1.stl" scale="0.001 0.001 0.001" />
            </geometry>
            <material name="silver" />
        </visual>
        <collision>
            <origin rpy="0 0 0" xyz="0.0 0.1126 -0.7934" />
            <geometry>
                <mesh filename="package://ur5_description/meshes/forearm_1.stl" scale="0.001 0.001 0.001" />
            </geometry>
        </collision>
    </link>
    <link name="wrist_1">
        <inertial>
            <origin rpy="0 0 0" xyz="1.221373912611945e-08 -0.06248572574196583 0.0015387505793551526" />
            <mass value="0.27456909234358" />
            <inertia ixx="0.014273" ixy="-0.0" ixz="-0.0" iyy="0.010388" iyz="0.000361" izz="0.011811" />
        </inertial>
        <visual>
            <origin rpy="0 0 0" xyz="-0.0 0.0957 -1.364735" />
            <geometry>
                <mesh filename="package://ur5_description/meshes/wrist_1.stl" scale="0.001 0.001 0.001" />
            </geometry>
            <material name="silver" />
        </visual>
        <collision>
            <origin rpy="0 0 0" xyz="-0.0 0.0957 -1.364735" />
            <geometry>
                <mesh filename="package://ur5_description/meshes/wrist_1.stl" scale="0.001 0.001 0.001" />
            </geometry>
        </collision>
    </link>
    <link name="end_1">
        <inertial>
            <origin rpy="0 0 0" xyz="2.901738992434707e-07 -0.001724242336090448 0.05332507883002502" />
            <mass value="0.195239059350037" />
            <inertia ixx="0.011265" ixy="-0.0" ixz="-0.0" iyy="0.008806" iyz="0.000289" izz="0.009591" />
        </inertial>
        <visual>
            <origin rpy="0 0 0" xyz="-0.0 0.17415 -1.421635" />
            <geometry>
                <mesh filename="package://ur5_description/meshes/end_1.stl" scale="0.001 0.001 0.001" />
            </geometry>
            <material name="silver" />
        </visual>
        <collision>
            <origin rpy="0 0 0" xyz="-0.0 0.17415 -1.421635" />
            <geometry>
                <mesh filename="package://ur5_description/meshes/end_1.stl" scale="0.001 0.001 0.001" />
            </geometry>
        </collision>
    </link>
    <link name="suction_1">
        <inertial>
            <origin rpy="0 0 0" xyz="6.961771223765484e-13 -0.027764546560901465 -0.00011193336601378334" />
            <mass value="0.0494649759637526" />
            <inertia ixx="0.002071" ixy="-0.0" ixz="-0.0" iyy="0.002723" iyz="-0.0" izz="0.002082" />
        </inertial>
        <visual>
            <origin rpy="0 0 0" xyz="-0.0 0.23105 -1.484585" />
            <geometry>
                <mesh filename="package://ur5_description/meshes/suction_1.stl" scale="0.001 0.001 0.001" />
            </geometry>
            <material name="silver" />
        </visual>
        <collision>
            <origin rpy="0 0 0" xyz="-0.0 0.23105 -1.484585" />
            <geometry>
                <mesh filename="package://ur5_description/meshes/suction_1.stl" scale="0.001 0.001 0.001" />
            </geometry>
        </collision>
    </link>
    <joint name="base_joint" type="continuous">
        <origin rpy="0 0 0" xyz="0.0 0.0 0.0993" />
        <parent link="base_link" />
        <child link="shoulder_1" />
        <axis xyz="0.0 0.0 1.0" />
    </joint>
    <joint name="shoulder_joint" type="continuous">
        <origin rpy="0 0 0" xyz="0.0 -0.0946 0.0814" />
        <parent link="shoulder_1" />
        <child link="arm_1" />
        <axis xyz="-0.0 -1.0 0.0" />
    </joint>
    <joint name="arm_joint" type="revolute">
        <origin rpy="0 0 0" xyz="0.0 -0.018 0.6127" />
        <parent link="arm_1" />
        <child link="forearm_1" />
        <axis xyz="-0.0 1.0 -0.0" />
        <limit effort="100" lower="-2.879793" upper="2.879793" velocity="100" />
    </joint>
    <joint name="forearm_joint" type="continuous">
        <origin rpy="0 0 0" xyz="0.0 0.0169 0.571335" />
        <parent link="forearm_1" />
        <child link="wrist_1" />
        <axis xyz="0.0 -1.0 0.0" />
    </joint>
    <joint name="wrist_joint" type="continuous">
        <origin rpy="0 0 0" xyz="0.0 -0.07845 0.0569" />
        <parent link="wrist_1" />
        <child link="end_1" />
        <axis xyz="-0.0 0.0 1.0" />
    </joint>
    <joint name="suction_joint" type="fixed">
        <origin rpy="0 0 0" xyz="0.0 -0.0569 0.06295" />
        <parent link="end_1" />
        <child link="suction_1" />
        <axis xyz="0.0 -1.0 0.0" />
    </joint>
</robot>

