<?xml version="1.0" ?>
<robot name="ajgar" xmlns:xacro="http://www.ros.org/wiki/xacro">

<xacro:include filename="$(find ajgar_description)/urdf/materials.xacro" />
<xacro:include filename="$(find ajgar_description)/urdf/ajgar.trans" />
<xacro:include filename="$(find ajgar_description)/urdf/ajgar.gazebo" />

<link name="world"/>

<link name="base_link">
  <inertial>
    <origin xyz="0.010103886841160791 4.8949101223729115e-08 0.02317831708847054" rpy="0 0 0"/>
    <mass value="5.004539313789304"/>
    <inertia ixx="0.013906" iyy="0.018178" izz="0.029014" ixy="-0.0" iyz="-0.0" ixz="-0.0"/>
  </inertial>
  <visual>
    <origin xyz="0 0 0" rpy="0 0 0"/>
    <geometry>
      <mesh filename="package://ajgar_description/meshes/base_link.stl" scale="0.001 0.001 0.001"/>
    </geometry>
    <material name="silver"/>
  </visual>
  <collision>
    <origin xyz="0 0 0" rpy="0 0 0"/>
    <geometry>
      <mesh filename="package://ajgar_description/meshes/base_link.stl" scale="0.001 0.001 0.001"/>
    </geometry>
  </collision>
</link>

<link name="base_top">
  <inertial>
    <origin xyz="0.0004082185165979145 -0.0015396774573415422 0.05552164856674979" rpy="0 0 0"/>
    <mass value="0.446819319233817"/>
    <inertia ixx="0.00111" iyy="0.000992" izz="0.00053" ixy="-6e-06" iyz="4.9e-05" ixz="3.9e-05"/>
  </inertial>
  <visual>
    <origin xyz="0.0 -0.0 -0.049" rpy="0 0 0"/>
    <geometry>
      <mesh filename="package://ajgar_description/meshes/base_top.stl" scale="0.001 0.001 0.001"/>
    </geometry>
    <material name="silver"/>
  </visual>
  <collision>
    <origin xyz="0.0 -0.0 -0.049" rpy="0 0 0"/>
    <geometry>
      <mesh filename="package://ajgar_description/meshes/base_top.stl" scale="0.001 0.001 0.001"/>
    </geometry>
  </collision>
</link>

<link name="shoulder">
  <inertial>
    <origin xyz="9.375067755156181e-05 0.031352547630261414 0.16172845028521418" rpy="0 0 0"/>
    <mass value="4.919783093355411"/>
    <inertia ixx="0.043238" iyy="0.042205" izz="0.00519" ixy="-9e-06" iyz="-0.001721" ixz="-3.7e-05"/>
  </inertial>
  <visual>
    <origin xyz="0.005001 0.03 -0.174627" rpy="0 0 0"/>
    <geometry>
      <mesh filename="package://ajgar_description/meshes/shoulder.stl" scale="0.001 0.001 0.001"/>
    </geometry>
    <material name="silver"/>
  </visual>
  <collision>
    <origin xyz="0.005001 0.03 -0.174627" rpy="0 0 0"/>
    <geometry>
      <mesh filename="package://ajgar_description/meshes/shoulder.stl" scale="0.001 0.001 0.001"/>
    </geometry>
  </collision>
</link>

<link name="elbow">
  <inertial>
    <origin xyz="-0.00033678312678123504 -0.02797681411913612 0.07913310635318643" rpy="0 0 0"/>
    <mass value="2.365159547256585"/>
    <inertia ixx="0.012144" iyy="0.012502" izz="0.001475" ixy="-2e-06" iyz="-4e-06" ixz="8.9e-05"/>
  </inertial>
  <visual>
    <origin xyz="0.004596 -0.028 -0.453478" rpy="0 0 0"/>
    <geometry>
      <mesh filename="package://ajgar_description/meshes/elbow.stl" scale="0.001 0.001 0.001"/>
    </geometry>
    <material name="silver"/>
  </visual>
  <collision>
    <origin xyz="0.004596 -0.028 -0.453478" rpy="0 0 0"/>
    <geometry>
      <mesh filename="package://ajgar_description/meshes/elbow.stl" scale="0.001 0.001 0.001"/>
    </geometry>
  </collision>
</link>

<link name="wrist">
  <inertial>
    <origin xyz="0.00831118200669997 -0.01041937296016998 0.02550451373875129" rpy="0 0 0"/>
    <mass value="0.338076325355839"/>
    <inertia ixx="0.000584" iyy="0.00026" izz="0.000535" ixy="8.6e-05" iyz="7e-05" ixz="-5.5e-05"/>
  </inertial>
  <visual>
    <origin xyz="0.004596 0.0 -0.653478" rpy="0 0 0"/>
    <geometry>
      <mesh filename="package://ajgar_description/meshes/wrist.stl" scale="0.001 0.001 0.001"/>
    </geometry>
    <material name="silver"/>
  </visual>
  <collision>
    <origin xyz="0.004596 0.0 -0.653478" rpy="0 0 0"/>
    <geometry>
      <mesh filename="package://ajgar_description/meshes/wrist.stl" scale="0.001 0.001 0.001"/>
    </geometry>
  </collision>
</link>

<link name="suction">
  <inertial>
    <origin xyz="-8.479128018760562e-05 0.03652029926030631 8.946794887854104e-05" rpy="0 0 0"/>
    <mass value="0.605324576914463"/>
    <inertia ixx="0.000476" iyy="0.000398" izz="0.000554" ixy="0.0" iyz="-0.0" ixz="1.7e-05"/>
  </inertial>
  <visual>
    <origin xyz="0.004596 0.037 -0.698478" rpy="0 0 0"/>
    <geometry>
      <mesh filename="package://ajgar_description/meshes/suction.stl" scale="0.001 0.001 0.001"/>
    </geometry>
    <material name="silver"/>
  </visual>
  <collision>
    <origin xyz="0.004596 0.037 -0.698478" rpy="0 0 0"/>
    <geometry>
      <mesh filename="package://ajgar_description/meshes/suction.stl" scale="0.001 0.001 0.001"/>
    </geometry>
  </collision>
</link>

<link name="end">
  <inertial>
    <origin xyz="-8.702208040972659e-08 -2.1072130740783367e-09 0.005896611642581373" rpy="0 0 0"/>
    <mass value="0.07642686015416068"/>
    <inertia ixx="7e-06" iyy="5e-06" izz="8e-06" ixy="0.0" iyz="-0.0" ixz="0.0"/>
  </inertial>
  <visual>
    <origin xyz="0.004596 0.0 -0.722978" rpy="0 0 0"/>
    <geometry>
      <mesh filename="package://ajgar_description/meshes/end.stl" scale="0.001 0.001 0.001"/>
    </geometry>
    <material name="silver"/>
  </visual>
  <collision>
    <origin xyz="0.004596 0.0 -0.722978" rpy="0 0 0"/>
    <geometry>
      <mesh filename="package://ajgar_description/meshes/end.stl" scale="0.001 0.001 0.001"/>
    </geometry>
  </collision>
</link>

<link name="camera_depth_frame">
  <collision>
    <origin xyz="0 0 0" rpy="1.57 0 0" />
    <geometry>
      <mesh filename="package://ur5_description/meshes/kinect.stl" scale="0.005 0.005 0.005" />
    </geometry>
  </collision>
  <visual>
    <origin xyz="0 0 0" rpy="1.57 -1.57 0" />
    <geometry>
      <mesh filename="package://ur5_description/meshes/kinect.stl" scale="0.005 0.005 0.005" />
    </geometry>
  </visual>
  <inertial>
    <mass value="1e-5" />
    <origin xyz="0 0 0" rpy="0 0 0" />
    <inertia ixx="1e-6" ixy="0" ixz="0" iyy="1e-6" iyz="0" izz="1e-6" />
  </inertial>
</link> 

<joint name="world_joint" type="fixed">
    <parent link="world" />
    <child link="base_link" />
    <origin rpy="0 0 3.142" xyz="0.0 0.0 0.0" />
</joint>

<joint name="base" type="revolute">
  <origin xyz="0.0 0.0 0.049" rpy="0 0 0"/>
  <parent link="base_link"/>
  <child link="base_top"/>
  <axis xyz="-0.0 0.0 1.0"/>
  <limit upper="3.14159" lower="-3.14159" effort="100" velocity="100" />
</joint>

<joint name="shoulder_joint" type="revolute">
  <origin xyz="-0.005001 -0.03 0.125627" rpy="0 0 0"/>
  <parent link="base_top"/>
  <child link="shoulder"/>
  <axis xyz="-0.0 1.0 -0.0"/>
  <limit upper="2.16421" lower="-2.33874" effort="100" velocity="100" />
</joint>

<joint name="elbow_joint" type="revolute">
  <origin xyz="0.000405 0.058 0.278851" rpy="0 0 0"/>
  <parent link="shoulder"/>
  <child link="elbow"/>
  <axis xyz="0.0 -1.0 0.0"/>
  <limit upper="2.79253" lower="-2.79253" effort="100" velocity="100" />
</joint>

<joint name="lower_wrist_joint" type="revolute">
  <origin xyz="0.0 -0.028 0.2" rpy="0 0 0"/>
  <parent link="elbow"/>
  <child link="wrist"/>
  <axis xyz="0.0 0.0 1.0"/>
    <limit upper="3.14159" lower="-3.14159" effort="100" velocity="100" />
</joint>

<joint name="upper_wrist_joint" type="revolute">
  <origin xyz="0.0 -0.037 0.045" rpy="0 0 0"/>
  <parent link="wrist"/>
  <child link="suction"/>
  <axis xyz="-0.0 1.0 -0.0"/>
    <limit upper="0.837758" lower="-2.58309" effort="100" velocity="100" />
</joint>

<joint name="end_joint" type="revolute">
  <origin xyz="0.0 0.037 0.0245" rpy="0 0 0"/>
  <parent link="suction"/>
  <child link="end"/>
  <axis xyz="-0.0 -0.0 -1.0"/>
    <limit upper="3.14159" lower="-3.14159" effort="100" velocity="100" />
</joint>

<joint name="kinect_joint" type="fixed">
  <origin xyz="0.612 -0.15 1.5" rpy="0 1.57 0" />
  <parent link="base_link" />
  <child link="camera_depth_frame" />
</joint>

</robot>
