<?xml version="1.0" ?>
<!-- =================================================================================== -->
<!-- |    This document was autogenerated by xacro from /home/arsenious/catkin_ws/src/flipkartGrid/nag_raj_description/urdf/nag_raj.xacro | -->
<!-- |    EDITING THIS FILE BY HAND IS NOT RECOMMENDED                                 | -->
<!-- =================================================================================== -->
<robot name="nag_raj">
    <material name="silver">
        <color rgba="0.700 0.700 0.700 1.000" />
    </material>
    <transmission name="Revolute 1_tran">
        <type>transmission_interface/SimpleTransmission</type>
        <joint name="Revolute 1">
            <hardwareInterface>hardware_interface/EffortJointInterface</hardwareInterface>
        </joint>
        <actuator name="Revolute 1_actr">
            <hardwareInterface>hardware_interface/EffortJointInterface</hardwareInterface>
            <mechanicalReduction>1</mechanicalReduction>
        </actuator>
    </transmission>
    <transmission name="Revolute 2_tran">
        <type>transmission_interface/SimpleTransmission</type>
        <joint name="Revolute 2">
            <hardwareInterface>hardware_interface/EffortJointInterface</hardwareInterface>
        </joint>
        <actuator name="Revolute 2_actr">
            <hardwareInterface>hardware_interface/EffortJointInterface</hardwareInterface>
            <mechanicalReduction>1</mechanicalReduction>
        </actuator>
    </transmission>
    <transmission name="Revolute 3_tran">
        <type>transmission_interface/SimpleTransmission</type>
        <joint name="Revolute 3">
            <hardwareInterface>hardware_interface/EffortJointInterface</hardwareInterface>
        </joint>
        <actuator name="Revolute 3_actr">
            <hardwareInterface>hardware_interface/EffortJointInterface</hardwareInterface>
            <mechanicalReduction>1</mechanicalReduction>
        </actuator>
    </transmission>
    <transmission name="Revolute 4_tran">
        <type>transmission_interface/SimpleTransmission</type>
        <joint name="Revolute 4">
            <hardwareInterface>hardware_interface/EffortJointInterface</hardwareInterface>
        </joint>
        <actuator name="Revolute 4_actr">
            <hardwareInterface>hardware_interface/EffortJointInterface</hardwareInterface>
            <mechanicalReduction>1</mechanicalReduction>
        </actuator>
    </transmission>
    <transmission name="Revolute 5_tran">
        <type>transmission_interface/SimpleTransmission</type>
        <joint name="Revolute 5">
            <hardwareInterface>hardware_interface/EffortJointInterface</hardwareInterface>
        </joint>
        <actuator name="Revolute 5_actr">
            <hardwareInterface>hardware_interface/EffortJointInterface</hardwareInterface>
            <mechanicalReduction>1</mechanicalReduction>
        </actuator>
    </transmission>
    <gazebo>
        <plugin filename="libgazebo_ros_control.so" name="control" />
        <plugin name="gazebo_ros_control">
            <robotNamespace>/</robotNamespace>
        </plugin>
    </gazebo>
    <gazebo reference="base_link">
        <material>Gazebo/Silver</material>
        <mu1>0.2</mu1>
        <mu2>0.2</mu2>
        <selfCollide>true</selfCollide>
        <gravity>true</gravity>
    </gazebo>
    <gazebo reference="sh_joint_1">
        <material>Gazebo/Silver</material>
        <mu1>0.2</mu1>
        <mu2>0.2</mu2>
        <selfCollide>true</selfCollide>
    </gazebo>
    <gazebo reference="shoulder_1">
        <material>Gazebo/Silver</material>
        <mu1>0.2</mu1>
        <mu2>0.2</mu2>
        <selfCollide>true</selfCollide>
    </gazebo>
    <gazebo reference="elbow1_1">
        <material>Gazebo/Silver</material>
        <mu1>0.2</mu1>
        <mu2>0.2</mu2>
        <selfCollide>true</selfCollide>
    </gazebo>
    <gazebo reference="elbow2_1">
        <material>Gazebo/Silver</material>
        <mu1>0.2</mu1>
        <mu2>0.2</mu2>
        <selfCollide>true</selfCollide>
    </gazebo>
    <gazebo reference="wrist_1">
        <material>Gazebo/Silver</material>
        <mu1>0.2</mu1>
        <mu2>0.2</mu2>
        <selfCollide>true</selfCollide>
    </gazebo>
    <link name="base_link">
        <inertial>
            <origin rpy="0 0 0" xyz="-0.0006379139080881657 -0.01809373210164651 0.030365961397063188" />
            <mass value="12.627463545285623" />
            <inertia ixx="0.031143" ixy="-0.000405" ixz="-7e-05" iyy="0.030205" iyz="0.000267" izz="0.052676" />
        </inertial>
        <visual>
            <origin rpy="0 0 0" xyz="0 0 0" />
            <geometry>
                <mesh filename="package://nag_raj_description/meshes/base_link.stl" scale="0.001 0.001 0.001" />
            </geometry>
            <material name="silver" />
        </visual>
        <collision>
            <origin rpy="0 0 0" xyz="0 0 0" />
            <geometry>
                <mesh filename="package://nag_raj_description/meshes/base_link.stl" scale="0.001 0.001 0.001" />
            </geometry>
        </collision>
    </link>
    <link name="sh_joint_1">
        <inertial>
            <origin rpy="0 0 0" xyz="-0.0011960436685277943 0.0013481214024438706 0.07489085893279906" />
            <mass value="29.69776516715868" />
            <inertia ixx="0.099358" ixy="0.016934" ixz="-0.000187" iyy="0.132845" iyz="3.3e-05" izz="0.135929" />
        </inertial>
        <visual>
            <origin rpy="0 0 0" xyz="0.001039 0.018393 -0.067132" />
            <geometry>
                <mesh filename="package://nag_raj_description/meshes/sh_joint_1.stl" scale="0.001 0.001 0.001" />
            </geometry>
            <material name="silver" />
        </visual>
        <collision>
            <origin rpy="0 0 0" xyz="0.001039 0.018393 -0.067132" />
            <geometry>
                <mesh filename="package://nag_raj_description/meshes/sh_joint_1.stl" scale="0.001 0.001 0.001" />
            </geometry>
        </collision>
    </link>
    <link name="shoulder_1">
        <inertial>
            <origin rpy="0 0 0" xyz="0.007821760472450007 0.2778220009300011 0.03125519386875361" />
            <mass value="89.21154259038471" />
            <inertia ixx="4.45732" ixy="-1.710485" ixz="-0.232136" iyy="1.046726" iyz="-0.557906" izz="5.155255" />
        </inertial>
        <visual>
            <origin rpy="0 0 0" xyz="0.093573 -0.021145 -0.146342" />
            <geometry>
                <mesh filename="package://nag_raj_description/meshes/shoulder_1.stl" scale="0.001 0.001 0.001" />
            </geometry>
            <material name="silver" />
        </visual>
        <collision>
            <origin rpy="0 0 0" xyz="0.093573 -0.021145 -0.146342" />
            <geometry>
                <mesh filename="package://nag_raj_description/meshes/shoulder_1.stl" scale="0.001 0.001 0.001" />
            </geometry>
        </collision>
    </link>
    <link name="elbow1_1">
        <inertial>
            <origin rpy="0 0 0" xyz="0.012063915743866088 -0.08935136984735537 0.01819736606366848" />
            <mass value="12.818945015869657" />
            <inertia ixx="0.078237" ixy="-0.01847" ixz="0.004333" iyy="0.022075" iyz="0.01453" izz="0.079476" />
        </inertial>
        <visual>
            <origin rpy="0 0 0" xyz="-0.129699 -0.612043 -0.224144" />
            <geometry>
                <mesh filename="package://nag_raj_description/meshes/elbow1_1.stl" scale="0.001 0.001 0.001" />
            </geometry>
            <material name="silver" />
        </visual>
        <collision>
            <origin rpy="0 0 0" xyz="-0.129699 -0.612043 -0.224144" />
            <geometry>
                <mesh filename="package://nag_raj_description/meshes/elbow1_1.stl" scale="0.001 0.001 0.001" />
            </geometry>
        </collision>
    </link>
    <link name="elbow2_1">
        <inertial>
            <origin rpy="0 0 0" xyz="-0.06172372576999953 -0.1471990074107003 0.039999758385676654" />
            <mass value="14.074723611721877" />
            <inertia ixx="0.09516" ixy="-0.030922" ixz="0.008622" iyy="0.034386" iyz="0.020824" izz="0.105805" />
        </inertial>
        <visual>
            <origin rpy="0 0 0" xyz="-0.092673 -0.388118 -0.275308" />
            <geometry>
                <mesh filename="package://nag_raj_description/meshes/elbow2_1.stl" scale="0.001 0.001 0.001" />
            </geometry>
            <material name="silver" />
        </visual>
        <collision>
            <origin rpy="0 0 0" xyz="-0.092673 -0.388118 -0.275308" />
            <geometry>
                <mesh filename="package://nag_raj_description/meshes/elbow2_1.stl" scale="0.001 0.001 0.001" />
            </geometry>
        </collision>
    </link>
    <link name="wrist_1">
        <inertial>
            <origin rpy="0 0 0" xyz="-0.05432751125838708 0.017695228247820827 -0.0008664628207630809" />
            <mass value="5.82092033198201" />
            <inertia ixx="0.006574" ixy="0.000912" ixz="-5e-05" iyy="0.008357" iyz="0.000122" izz="0.009234" />
        </inertial>
        <visual>
            <origin rpy="0 0 0" xyz="0.055527 -0.184746 -0.334878" />
            <geometry>
                <mesh filename="package://nag_raj_description/meshes/wrist_1.stl" scale="0.001 0.001 0.001" />
            </geometry>
            <material name="silver" />
        </visual>
        <collision>
            <origin rpy="0 0 0" xyz="0.055527 -0.184746 -0.334878" />
            <geometry>
                <mesh filename="package://nag_raj_description/meshes/wrist_1.stl" scale="0.001 0.001 0.001" />
            </geometry>
        </collision>
    </link>
    <joint name="Revolute 1" type="continuous">
        <origin rpy="0 0 0" xyz="-0.001039 -0.018393 0.067132" />
        <parent link="base_link" />
        <child link="sh_joint_1" />
        <axis xyz="-0.0032 0.012661 0.999915" />
    </joint>
    <joint name="Revolute 2" type="continuous">
        <origin rpy="0 0 0" xyz="-0.092534 0.039538 0.07921" />
        <parent link="sh_joint_1" />
        <child link="shoulder_1" />
        <axis xyz="-0.922781 0.385244 -0.007831" />
    </joint>
    <joint name="Revolute 3" type="revolute">
        <origin rpy="0 0 0" xyz="0.223272 0.590898 0.077802" />
        <parent link="shoulder_1" />
        <child link="elbow1_1" />
        <axis xyz="0.922781 -0.385244 0.007831" />
        <limit effort="100" lower="-5.585054" upper="0.0" velocity="100" />
    </joint>
    <joint name="Revolute 4" type="continuous">
        <origin rpy="0 0 0" xyz="-0.037026 -0.223925 0.051164" />
        <parent link="elbow1_1" />
        <child link="elbow2_1" />
        <axis xyz="-0.374756 -0.892561 0.250786" />
    </joint>
    <joint name="Revolute 5" type="continuous">
        <origin rpy="0 0 0" xyz="-0.1482 -0.203372 0.05957" />
        <parent link="elbow2_1" />
        <child link="wrist_1" />
        <axis xyz="-0.924511 0.380059 -0.02887" />
    </joint>
</robot>

