<?xml version="1.0" ?>
<!-- =================================================================================== -->
<!-- |    This document was autogenerated by xacro from /home/arsenious/catkin_ws/src/ajgar/urdf/ajgar.xacro | -->
<!-- |    EDITING THIS FILE BY HAND IS NOT RECOMMENDED                                 | -->
<!-- =================================================================================== -->
<robot name="ajgar">
    <material name="silver">
        <color rgba="0.700 0.700 0.700 1.000" />
    </material>
    <transmission name="base_joint_tran">
        <type>transmission_interface/SimpleTransmission</type>
        <joint name="base_joint">
            <hardwareInterface>hardware_interface/EffortJointInterface</hardwareInterface>
        </joint>
        <actuator name="base_joint_actr">
            <hardwareInterface>hardware_interface/EffortJointInterface</hardwareInterface>
            <mechanicalReduction>1</mechanicalReduction>
        </actuator>
    </transmission>
    <transmission name="shoulder_joint_tran">
        <type>transmission_interface/SimpleTransmission</type>
        <joint name="shoulder_joint">
            <hardwareInterface>hardware_interface/EffortJointInterface</hardwareInterface>
        </joint>
        <actuator name="shoulder_joint_actr">
            <hardwareInterface>hardware_interface/EffortJointInterface</hardwareInterface>
            <mechanicalReduction>1</mechanicalReduction>
        </actuator>
    </transmission>
    <transmission name="arm_joint_tran">
        <type>transmission_interface/SimpleTransmission</type>
        <joint name="arm_joint ">
            <hardwareInterface>hardware_interface/EffortJointInterface</hardwareInterface>
        </joint>
        <actuator name="arm_joint_actr">
            <hardwareInterface>hardware_interface/EffortJointInterface</hardwareInterface>
            <mechanicalReduction>1</mechanicalReduction>
        </actuator>
    </transmission>
    <transmission name="forearm_joint_tran">
        <type>transmission_interface/SimpleTransmission</type>
        <joint name="forearm_joint">
            <hardwareInterface>hardware_interface/EffortJointInterface</hardwareInterface>
        </joint>
        <actuator name="forearm_joint_actr">
            <hardwareInterface>hardware_interface/EffortJointInterface</hardwareInterface>
            <mechanicalReduction>1</mechanicalReduction>
        </actuator>
    </transmission>
    <transmission name="end_joint_tran">
        <type>transmission_interface/SimpleTransmission</type>
        <joint name="end_joint">
            <hardwareInterface>hardware_interface/EffortJointInterface</hardwareInterface>
        </joint>
        <actuator name="end_joint_actr">
            <hardwareInterface>hardware_interface/EffortJointInterface</hardwareInterface>
            <mechanicalReduction>1</mechanicalReduction>
        </actuator>
    </transmission>
    <transmission name="suction_joint_tran">
        <type>transmission_interface/SimpleTransmission</type>
        <joint name="suction_joint">
            <hardwareInterface>hardware_interface/EffortJointInterface</hardwareInterface>
        </joint>
        <actuator name="suction_joint_actr">
            <hardwareInterface>hardware_interface/EffortJointInterface</hardwareInterface>
            <mechanicalReduction>1</mechanicalReduction>
        </actuator>
    </transmission>
    <gazebo>
        <plugin filename="libgazebo_ros_control.so" name="control" />
        <plugin name="gazebo_ros_control">
            <robotNamespace>/</robotNamespace>
        </plugin>
    </gazebo>
    <gazebo reference="base_link">
        <material>Gazebo/Silver</material>
        <mu1>0.2</mu1>
        <mu2>0.2</mu2>
        <selfCollide>true</selfCollide>
        <gravity>true</gravity>
    </gazebo>
    <gazebo reference="base_top">
        <material>Gazebo/Silver</material>
        <mu1>0.2</mu1>
        <mu2>0.2</mu2>
        <selfCollide>true</selfCollide>
    </gazebo>
    <gazebo reference="shoulder">
        <material>Gazebo/Silver</material>
        <mu1>0.2</mu1>
        <mu2>0.2</mu2>
        <selfCollide>true</selfCollide>
    </gazebo>
    <gazebo reference="elbow">
        <material>Gazebo/Silver</material>
        <mu1>0.2</mu1>
        <mu2>0.2</mu2>
        <selfCollide>true</selfCollide>
    </gazebo>
    <gazebo reference="wrist">
        <material>Gazebo/Silver</material>
        <mu1>0.2</mu1>
        <mu2>0.2</mu2>
        <selfCollide>true</selfCollide>
    </gazebo>
    <gazebo reference="suction">
        <material>Gazebo/Silver</material>
        <mu1>0.2</mu1>
        <mu2>0.2</mu2>
        <selfCollide>true</selfCollide>
    </gazebo>
    <gazebo reference="end">
        <material>Gazebo/Silver</material>
        <mu1>0.2</mu1>
        <mu2>0.2</mu2>
        <selfCollide>true</selfCollide>
    </gazebo>
    <link name="base_link">
        <inertial>
            <origin rpy="0 0 0" xyz="-0.00865082588772432 1.8113911902102217e-07 0.032368373908884494" />
            <mass value="9.059758934586307" />
            <inertia ixx="0.021583" ixy="-0.0" ixz="0.000269" iyy="0.026795" iyz="-0.0" izz="0.042202" />
        </inertial>
        <visual>
            <origin rpy="0 0 0" xyz="0 0 0" />
            <geometry>
                <mesh filename="package://ajgar/meshes/base_link.stl" scale="0.001 0.001 0.001" />
            </geometry>
            <material name="silver" />
        </visual>
        <collision>
            <origin rpy="0 0 0" xyz="0 0 0" />
            <geometry>
                <mesh filename="package://ajgar/meshes/base_link.stl" scale="0.001 0.001 0.001" />
            </geometry>
        </collision>
    </link>
    <link name="base_top">
        <inertial>
            <origin rpy="0 0 0" xyz="1.279003402099646e-05 -0.0022856514871783416 0.03289309768621855" />
            <mass value="1.4850383611977547" />
            <inertia ixx="0.002124" ixy="-0.0" ixz="0.0" iyy="0.00176" iyz="0.000118" izz="0.001747" />
        </inertial>
        <visual>
            <origin rpy="0 0 0" xyz="0.015013 -0.0 -0.06" />
            <geometry>
                <mesh filename="package://ajgar/meshes/base_top.stl" scale="0.001 0.001 0.001" />
            </geometry>
            <material name="silver" />
        </visual>
        <collision>
            <origin rpy="0 0 0" xyz="0.015013 -0.0 -0.06" />
            <geometry>
                <mesh filename="package://ajgar/meshes/base_top.stl" scale="0.001 0.001 0.001" />
            </geometry>
        </collision>
    </link>
    <link name="shoulder">
        <inertial>
            <origin rpy="0 0 0" xyz="1.2461762721963782e-06 0.025783530669485587 0.11928257744286477" />
            <mass value="2.8383656665985857" />
            <inertia ixx="0.03026" ixy="-0.0" ixz="0.0" iyy="0.030184" iyz="0.000773" izz="0.00245" />
        </inertial>
        <visual>
            <origin rpy="0 0 0" xyz="0.015013 0.025 -0.119368" />
            <geometry>
                <mesh filename="package://ajgar/meshes/shoulder.stl" scale="0.001 0.001 0.001" />
            </geometry>
            <material name="silver" />
        </visual>
        <collision>
            <origin rpy="0 0 0" xyz="0.015013 0.025 -0.119368" />
            <geometry>
                <mesh filename="package://ajgar/meshes/shoulder.stl" scale="0.001 0.001 0.001" />
            </geometry>
        </collision>
    </link>
    <link name="elbow">
        <inertial>
            <origin rpy="0 0 0" xyz="-0.0003292153850686253 0.026723336517713626 0.10654902767889785" />
            <mass value="2.4072821039747727" />
            <inertia ixx="0.026455" ixy="-4e-06" ixz="0.000123" iyy="0.026758" iyz="0.000315" izz="0.001672" />
        </inertial>
        <visual>
            <origin rpy="0 0 0" xyz="0.015013 0.025 -0.377365" />
            <geometry>
                <mesh filename="package://ajgar/meshes/elbow.stl" scale="0.001 0.001 0.001" />
            </geometry>
            <material name="silver" />
        </visual>
        <collision>
            <origin rpy="0 0 0" xyz="0.015013 0.025 -0.377365" />
            <geometry>
                <mesh filename="package://ajgar/meshes/elbow.stl" scale="0.001 0.001 0.001" />
            </geometry>
        </collision>
    </link>
    <link name="wrist">
        <inertial>
            <origin rpy="0 0 0" xyz="0.00920373509392226 -0.01118771679377522 0.025837849583827288" />
            <mass value="0.34678950211541076" />
            <inertia ixx="0.000595" ixy="9.5e-05" ixz="-6e-05" iyy="0.000274" iyz="7.4e-05" izz="0.000554" />
        </inertial>
        <visual>
            <origin rpy="0 0 0" xyz="0.015013 -0.0 -0.644865" />
            <geometry>
                <mesh filename="package://ajgar/meshes/wrist.stl" scale="0.001 0.001 0.001" />
            </geometry>
            <material name="silver" />
        </visual>
        <collision>
            <origin rpy="0 0 0" xyz="0.015013 -0.0 -0.644865" />
            <geometry>
                <mesh filename="package://ajgar/meshes/wrist.stl" scale="0.001 0.001 0.001" />
            </geometry>
        </collision>
    </link>
    <link name="suction">
        <inertial>
            <origin rpy="0 0 0" xyz="-8.479527444330004e-05 0.03652030172582285 8.898889773256702e-05" />
            <mass value="0.6053245769138885" />
            <inertia ixx="0.000476" ixy="0.0" ixz="1.7e-05" iyy="0.000398" iyz="-0.0" izz="0.000554" />
        </inertial>
        <visual>
            <origin rpy="0 0 0" xyz="0.015013 0.037 -0.689865" />
            <geometry>
                <mesh filename="package://ajgar/meshes/suction.stl" scale="0.001 0.001 0.001" />
            </geometry>
            <material name="silver" />
        </visual>
        <collision>
            <origin rpy="0 0 0" xyz="0.015013 0.037 -0.689865" />
            <geometry>
                <mesh filename="package://ajgar/meshes/suction.stl" scale="0.001 0.001 0.001" />
            </geometry>
        </collision>
    </link>
    <link name="end">
        <inertial>
            <origin rpy="0 0 0" xyz="-9.118561992635388e-08 3.576502294322381e-10 -0.00900061967229826" />
            <mass value="0.07630173554088619" />
            <inertia ixx="7e-06" ixy="0.0" ixz="0.0" iyy="5e-06" iyz="-0.0" izz="8e-06" />
        </inertial>
        <visual>
            <origin rpy="0 0 0" xyz="0.015013 -0.0 -0.714365" />
            <geometry>
                <mesh filename="package://ajgar/meshes/end.stl" scale="0.001 0.001 0.001" />
            </geometry>
            <material name="silver" />
        </visual>
        <collision>
            <origin rpy="0 0 0" xyz="0.015013 -0.0 -0.714365" />
            <geometry>
                <mesh filename="package://ajgar/meshes/end.stl" scale="0.001 0.001 0.001" />
            </geometry>
        </collision>
    </link>
    <joint name="base_joint" type="continuous">
        <origin rpy="0 0 0" xyz="-0.015013 0.0 0.06" />
        <parent link="base_link" />
        <child link="base_top" />
        <axis xyz="0.0 0.0 1.0" />
    </joint>
    <joint name="shoulder_joint" type="continuous">
        <origin rpy="0 0 0" xyz="0.0 -0.025 0.059368" />
        <parent link="base_top" />
        <child link="shoulder" />
        <axis xyz="0.0 -1.0 0.0" />
    </joint>
    <joint name="arm_joint" type="continuous">
        <origin rpy="0 0 0" xyz="0.0 0.0 0.257997" />
        <parent link="shoulder" />
        <child link="elbow" />
        <axis xyz="0.0 -1.0 -0.0" />
    </joint>
    <joint name="forearm_joint" type="continuous">
        <origin rpy="0 0 0" xyz="0.0 0.025 0.2675" />
        <parent link="elbow" />
        <child link="wrist" />
        <axis xyz="-0.0 0.0 1.0" />
    </joint>
    <joint name="end_joint" type="continuous">
        <origin rpy="0 0 0" xyz="0.0 -0.037 0.045" />
        <parent link="wrist" />
        <child link="suction" />
        <axis xyz="-0.0 1.0 -0.0" />
    </joint>
    <joint name="suction_joint" type="continuous">
        <origin rpy="0 0 0" xyz="0.0 0.037 0.0245" />
        <parent link="suction" />
        <child link="end" />
        <axis xyz="-0.0 -0.0 -1.0" />
    </joint>
    <transmission name="trans_arm_joint">
        <type>transmission_interface/SimpleTransmission</type>
        <joint name="arm_joint">
            <hardwareInterface>hardware_interface/EffortJointInterface</hardwareInterface>
        </joint>
        <actuator name="arm_joint_motor">
            <hardwareInterface>hardware_interface/EffortJointInterface</hardwareInterface>
            <mechanicalReduction>1</mechanicalReduction>
        </actuator>
    </transmission>
</robot>
