<?xml version="1.0" ?>
<!-- =================================================================================== -->
<!-- |    This document was autogenerated by xacro from /home/jc/flipkartGrid_ws/src/flipkartGrid/ajgar/urdf/ajgar_URDF.xacro | -->
<!-- |    EDITING THIS FILE BY HAND IS NOT RECOMMENDED                                 | -->
<!-- =================================================================================== -->
<robot name="ajgar">
    <material name="silver">
        <color rgba="0.700 0.700 0.700 1.000" />
    </material>
    <transmission name="base_tran">
        <type>transmission_interface/SimpleTransmission</type>
        <joint name="base">
            <hardwareInterface>hardware_interface/PositionJointInterface</hardwareInterface>
        </joint>
        <actuator name="base_actr">
            <hardwareInterface>hardware_interface/PositionJointInterface</hardwareInterface>
            <mechanicalReduction>1</mechanicalReduction>
        </actuator>
    </transmission>
    <transmission name="shoulder_joint_tran">
        <type>transmission_interface/SimpleTransmission</type>
        <joint name="shoulder_joint">
            <hardwareInterface>hardware_interface/PositionJointInterface</hardwareInterface>
        </joint>
        <actuator name="shoulder_joint_actr">
            <hardwareInterface>hardware_interface/PositionJointInterface</hardwareInterface>
            <mechanicalReduction>1</mechanicalReduction>
        </actuator>
    </transmission>
    <transmission name="elbow_joint_tran">
        <type>transmission_interface/SimpleTransmission</type>
        <joint name="elbow_joint">
            <hardwareInterface>hardware_interface/PositionJointInterface</hardwareInterface>
        </joint>
        <actuator name="elbow_joint_actr">
            <hardwareInterface>hardware_interface/PositionJointInterface</hardwareInterface>
            <mechanicalReduction>1</mechanicalReduction>
        </actuator>
    </transmission>
    <transmission name="lower_wrist_joint_tran">
        <type>transmission_interface/SimpleTransmission</type>
        <joint name="lower_wrist_joint">
            <hardwareInterface>hardware_interface/PositionJointInterface</hardwareInterface>
        </joint>
        <actuator name="lower_wrist_joint_actr">
            <hardwareInterface>hardware_interface/PositionJointInterface</hardwareInterface>
            <mechanicalReduction>1</mechanicalReduction>
        </actuator>
    </transmission>
    <transmission name="upper_wrist_joint_tran">
        <type>transmission_interface/SimpleTransmission</type>
        <joint name="upper_wrist_joint">
            <hardwareInterface>hardware_interface/PositionJointInterface</hardwareInterface>
        </joint>
        <actuator name="upper_wrist_joint_actr">
            <hardwareInterface>hardware_interface/PositionJointInterface</hardwareInterface>
            <mechanicalReduction>1</mechanicalReduction>
        </actuator>
    </transmission>
    <transmission name="end_joint_tran">
        <type>transmission_interface/SimpleTransmission</type>
        <joint name="end_joint">
            <hardwareInterface>hardware_interface/PositionJointInterface</hardwareInterface>
        </joint>
        <actuator name="end_joint_actr">
            <hardwareInterface>hardware_interface/PositionJointInterface</hardwareInterface>
            <mechanicalReduction>1</mechanicalReduction>
        </actuator>
    </transmission>
    <gazebo>
        <plugin filename="libgazebo_ros_control.so" name="control" />
        <plugin name="gazebo_ros_control">
            <robotNamespace>/</robotNamespace>
        </plugin>
    </gazebo>
    <gazebo reference="base_link">
        <material>Gazebo/Silver</material>
        <mu1>0.2</mu1>
        <mu2>0.2</mu2>
        <selfCollide>true</selfCollide>
        <gravity>true</gravity>
    </gazebo>
    <gazebo reference="base_top">
        <material>Gazebo/Silver</material>
        <mu1>0.2</mu1>
        <mu2>0.2</mu2>
        <selfCollide>true</selfCollide>
    </gazebo>
    <gazebo reference="shoulder">
        <material>Gazebo/Silver</material>
        <mu1>0.2</mu1>
        <mu2>0.2</mu2>
        <selfCollide>true</selfCollide>
    </gazebo>
    <gazebo reference="elbow">
        <material>Gazebo/Silver</material>
        <mu1>0.2</mu1>
        <mu2>0.2</mu2>
        <selfCollide>true</selfCollide>
    </gazebo>
    <gazebo reference="wrist">
        <material>Gazebo/Silver</material>
        <mu1>0.2</mu1>
        <mu2>0.2</mu2>
        <selfCollide>true</selfCollide>
    </gazebo>
    <gazebo reference="suction">
        <material>Gazebo/Silver</material>
        <mu1>0.2</mu1>
        <mu2>0.2</mu2>
        <selfCollide>true</selfCollide>
    </gazebo>
    <gazebo reference="end">
        <material>Gazebo/Silver</material>
        <mu1>0.2</mu1>
        <mu2>0.2</mu2>
        <selfCollide>true</selfCollide>
    </gazebo>
    <link name="world" />
    <link name="base_link">
        <inertial>
            <origin rpy="0 0 0" xyz="0.010103886841160791 4.8949101223729115e-08 0.02317831708847054" />
            <mass value="5.004539313789304" />
            <inertia ixx="0.013906" ixy="-0.0" ixz="-0.0" iyy="0.018178" iyz="-0.0" izz="0.029014" />
        </inertial>
        <visual>
            <origin rpy="0 0 0" xyz="0 0 0" />
            <geometry>
                <mesh filename="package://ajgar/meshes/base_link.stl" scale="0.001 0.001 0.001" />
            </geometry>
            <material name="silver" />
        </visual>
        <collision>
            <origin rpy="0 0 0" xyz="0 0 0" />
            <geometry>
                <mesh filename="package://ajgar/meshes/base_link.stl" scale="0.001 0.001 0.001" />
            </geometry>
        </collision>
    </link>
    <link name="base_top">
        <inertial>
            <origin rpy="0 0 0" xyz="0.0004082185165979145 -0.0015396774573415422 0.05552164856674979" />
            <mass value="0.446819319233817" />
            <inertia ixx="0.00111" ixy="-6e-06" ixz="3.9e-05" iyy="0.000992" iyz="4.9e-05" izz="0.00053" />
        </inertial>
        <visual>
            <origin rpy="0 0 0" xyz="0.0 -0.0 -0.049" />
            <geometry>
                <mesh filename="package://ajgar/meshes/base_top.stl" scale="0.001 0.001 0.001" />
            </geometry>
            <material name="silver" />
        </visual>
        <collision>
            <origin rpy="0 0 0" xyz="0.0 -0.0 -0.049" />
            <geometry>
                <mesh filename="package://ajgar/meshes/base_top.stl" scale="0.001 0.001 0.001" />
            </geometry>
        </collision>
    </link>
    <link name="shoulder">
        <inertial>
            <origin rpy="0 0 0" xyz="9.375067755156181e-05 0.031352547630261414 0.16172845028521418" />
            <mass value="4.919783093355411" />
            <inertia ixx="0.043238" ixy="-9e-06" ixz="-3.7e-05" iyy="0.042205" iyz="-0.001721" izz="0.00519" />
        </inertial>
        <visual>
            <origin rpy="0 0 0" xyz="0.005001 0.03 -0.174627" />
            <geometry>
                <mesh filename="package://ajgar/meshes/shoulder.stl" scale="0.001 0.001 0.001" />
            </geometry>
            <material name="silver" />
        </visual>
        <collision>
            <origin rpy="0 0 0" xyz="0.005001 0.03 -0.174627" />
            <geometry>
                <mesh filename="package://ajgar/meshes/shoulder.stl" scale="0.001 0.001 0.001" />
            </geometry>
        </collision>
    </link>
    <link name="elbow">
        <inertial>
            <origin rpy="0 0 0" xyz="-0.00033678312678123504 -0.02797681411913612 0.07913310635318643" />
            <mass value="2.365159547256585" />
            <inertia ixx="0.012144" ixy="-2e-06" ixz="8.9e-05" iyy="0.012502" iyz="-4e-06" izz="0.001475" />
        </inertial>
        <visual>
            <origin rpy="0 0 0" xyz="0.004596 -0.028 -0.453478" />
            <geometry>
                <mesh filename="package://ajgar/meshes/elbow.stl" scale="0.001 0.001 0.001" />
            </geometry>
            <material name="silver" />
        </visual>
        <collision>
            <origin rpy="0 0 0" xyz="0.004596 -0.028 -0.453478" />
            <geometry>
                <mesh filename="package://ajgar/meshes/elbow.stl" scale="0.001 0.001 0.001" />
            </geometry>
        </collision>
    </link>
    <link name="wrist">
        <inertial>
            <origin rpy="0 0 0" xyz="0.00831118200669997 -0.01041937296016998 0.02550451373875129" />
            <mass value="0.338076325355839" />
            <inertia ixx="0.000584" ixy="8.6e-05" ixz="-5.5e-05" iyy="0.00026" iyz="7e-05" izz="0.000535" />
        </inertial>
        <visual>
            <origin rpy="0 0 0" xyz="0.004596 0.0 -0.653478" />
            <geometry>
                <mesh filename="package://ajgar/meshes/wrist.stl" scale="0.001 0.001 0.001" />
            </geometry>
            <material name="silver" />
        </visual>
        <collision>
            <origin rpy="0 0 0" xyz="0.004596 0.0 -0.653478" />
            <geometry>
                <mesh filename="package://ajgar/meshes/wrist.stl" scale="0.001 0.001 0.001" />
            </geometry>
        </collision>
    </link>
    <link name="suction">
        <inertial>
            <origin rpy="0 0 0" xyz="-8.479128018760562e-05 0.03652029926030631 8.946794887854104e-05" />
            <mass value="0.605324576914463" />
            <inertia ixx="0.000476" ixy="0.0" ixz="1.7e-05" iyy="0.000398" iyz="-0.0" izz="0.000554" />
        </inertial>
        <visual>
            <origin rpy="0 0 0" xyz="0.004596 0.037 -0.698478" />
            <geometry>
                <mesh filename="package://ajgar/meshes/suction.stl" scale="0.001 0.001 0.001" />
            </geometry>
            <material name="silver" />
        </visual>
        <collision>
            <origin rpy="0 0 0" xyz="0.004596 0.037 -0.698478" />
            <geometry>
                <mesh filename="package://ajgar/meshes/suction.stl" scale="0.001 0.001 0.001" />
            </geometry>
        </collision>
    </link>
    <link name="end">
        <inertial>
            <origin rpy="0 0 0" xyz="-8.702208040972659e-08 -2.1072130740783367e-09 0.005896611642581373" />
            <mass value="0.07642686015416068" />
            <inertia ixx="7e-06" ixy="0.0" ixz="0.0" iyy="5e-06" iyz="-0.0" izz="8e-06" />
        </inertial>
        <visual>
            <origin rpy="0 0 0" xyz="0.004596 0.0 -0.722978" />
            <geometry>
                <mesh filename="package://ajgar/meshes/end.stl" scale="0.001 0.001 0.001" />
            </geometry>
            <material name="silver" />
        </visual>
        <collision>
            <origin rpy="0 0 0" xyz="0.004596 0.0 -0.722978" />
            <geometry>
                <mesh filename="package://ajgar/meshes/end.stl" scale="0.001 0.001 0.001" />
            </geometry>
        </collision>
    </link>
    <joint name="world_joint" type="fixed">
        <parent link="world" />
        <child link="base_link" />
        <origin rpy="0 0 3.142" xyz="0.0 0.0 0.0" />
    </joint>
    <joint name="base" type="continuous">
        <origin rpy="0 0 0" xyz="0.0 0.0 0.049" />
        <parent link="base_link" />
        <child link="base_top" />
        <axis xyz="-0.0 0.0 1.0" />
    </joint>
    <joint name="shoulder_joint" type="continuous">
        <origin rpy="0 0 0" xyz="-0.005001 -0.03 0.125627" />
        <parent link="base_top" />
        <child link="shoulder" />
        <axis xyz="-0.0 1.0 -0.0" />
    </joint>
    <joint name="elbow_joint" type="continuous">
        <origin rpy="0 0 0" xyz="0.000405 0.058 0.278851" />
        <parent link="shoulder" />
        <child link="elbow" />
        <axis xyz="0.0 -1.0 0.0" />
    </joint>
    <joint name="lower_wrist_joint" type="continuous">
        <origin rpy="0 0 0" xyz="0.0 -0.028 0.2" />
        <parent link="elbow" />
        <child link="wrist" />
        <axis xyz="0.0 0.0 1.0" />
    </joint>
    <joint name="upper_wrist_joint" type="continuous">
        <origin rpy="0 0 0" xyz="0.0 -0.037 0.045" />
        <parent link="wrist" />
        <child link="suction" />
        <axis xyz="-0.0 1.0 -0.0" />
    </joint>
    <joint name="end_joint" type="continuous">
        <origin rpy="0 0 0" xyz="0.0 0.037 0.0245" />
        <parent link="suction" />
        <child link="end" />
        <axis xyz="-0.0 -0.0 -1.0" />
    </joint>
</robot>

