<?xml version="1.0" ?>
<!-- =================================================================================== -->
<!-- |    This document was autogenerated by xacro from /home/jc/flipkartGrid_ws/src/ajgar/urdf/ajgar_URDF.xacro | -->
<!-- |    EDITING THIS FILE BY HAND IS NOT RECOMMENDED                                 | -->
<!-- =================================================================================== -->
<robot name="ajgar">
    <material name="silver">
        <color rgba="0.700 0.700 0.700 1.000" />
    </material>
    <transmission name="base_joint_tran">
        <type>transmission_interface/SimpleTransmission</type>
        <joint name="base_joint">
            <hardwareInterface>hardware_interface/PositionJointInterface</hardwareInterface>
        </joint>
        <actuator name="base_joint_actr">
            <hardwareInterface>hardware_interface/PositionJointInterface</hardwareInterface>
            <mechanicalReduction>1</mechanicalReduction>
        </actuator>
    </transmission>
    <transmission name="shoulder_joint_tran">
        <type>transmission_interface/SimpleTransmission</type>
        <joint name="shoulder_joint">
            <hardwareInterface>hardware_interface/PositionJointInterface</hardwareInterface>
        </joint>
        <actuator name="shoulder_joint_actr">
            <hardwareInterface>hardware_interface/PositionJointInterface</hardwareInterface>
            <mechanicalReduction>1</mechanicalReduction>
        </actuator>
    </transmission>
    <transmission name="suction_joint_tran">
        <type>transmission_interface/SimpleTransmission</type>
        <joint name="suction_joint">
            <hardwareInterface>hardware_interface/PositionJointInterface</hardwareInterface>
        </joint>
        <actuator name="suction_joint_actr">
            <hardwareInterface>hardware_interface/PositionJointInterface</hardwareInterface>
            <mechanicalReduction>1</mechanicalReduction>
        </actuator>
    </transmission>
    <transmission name="end_joint_tran">
        <type>transmission_interface/SimpleTransmission</type>
        <joint name="end_joint">
            <hardwareInterface>hardware_interface/PositionJointInterface</hardwareInterface>
        </joint>
        <actuator name="end_joint_actr">
            <hardwareInterface>hardware_interface/PositionJointInterface</hardwareInterface>
            <mechanicalReduction>1</mechanicalReduction>
        </actuator>
    </transmission>
    <transmission name="elbow_joint_tran">
        <type>transmission_interface/SimpleTransmission</type>
        <joint name="elbow_joint">
            <hardwareInterface>hardware_interface/PositionJointInterface</hardwareInterface>
        </joint>
        <actuator name="elbow_joint_actr">
            <hardwareInterface>hardware_interface/PositionJointInterface</hardwareInterface>
            <mechanicalReduction>1</mechanicalReduction>
        </actuator>
    </transmission>
    <gazebo>
        <plugin filename="libgazebo_ros_control.so" name="control" />
        <plugin name="gazebo_ros_control">
            <robotNamespace>/</robotNamespace>
        </plugin>
    </gazebo>
    <gazebo reference="base_link">
        <material>Gazebo/Silver</material>
        <mu1>0.2</mu1>
        <mu2>0.2</mu2>
        <selfCollide>true</selfCollide>
        <gravity>true</gravity>
    </gazebo>
    <gazebo reference="base_top">
        <material>Gazebo/Silver</material>
        <mu1>0.2</mu1>
        <mu2>0.2</mu2>
        <selfCollide>true</selfCollide>
    </gazebo>
    <gazebo reference="shoulder">
        <material>Gazebo/Silver</material>
        <mu1>0.2</mu1>
        <mu2>0.2</mu2>
        <selfCollide>true</selfCollide>
    </gazebo>
    <gazebo reference="suction">
        <material>Gazebo/Silver</material>
        <mu1>0.2</mu1>
        <mu2>0.2</mu2>
        <selfCollide>true</selfCollide>
    </gazebo>
    <gazebo reference="KINECT_XBOX">
        <material>Gazebo/Silver</material>
        <mu1>0.2</mu1>
        <mu2>0.2</mu2>
        <selfCollide>true</selfCollide>
    </gazebo>
    <gazebo reference="wrist">
        <material>Gazebo/Silver</material>
        <mu1>0.2</mu1>
        <mu2>0.2</mu2>
        <selfCollide>true</selfCollide>
    </gazebo>
    <gazebo reference="extrusion3">
        <material>Gazebo/Silver</material>
        <mu1>0.2</mu1>
        <mu2>0.2</mu2>
        <selfCollide>true</selfCollide>
    </gazebo>
    <gazebo reference="end">
        <material>Gazebo/Silver</material>
        <mu1>0.2</mu1>
        <mu2>0.2</mu2>
        <selfCollide>true</selfCollide>
    </gazebo>
    <gazebo reference="elbow">
        <material>Gazebo/Silver</material>
        <mu1>0.2</mu1>
        <mu2>0.2</mu2>
        <selfCollide>true</selfCollide>
    </gazebo>
    <link name="base_link">
        <inertial>
            <origin rpy="0 0 0" xyz="-0.013996345982719845 0.05244124652798866 -0.05438727935716892" />
            <mass value="8.92124295451605" />
            <inertia ixx="0.018904" ixy="-0.0" ixz="0.000101" iyy="0.023843" iyz="-1e-06" izz="0.038855" />
        </inertial>
        <visual>
            <origin rpy="0 0 0" xyz="0 0 0" />
            <geometry>
                <mesh filename="package://ajgar/meshes/base_link.stl" scale="0.001 0.001 0.001" />
            </geometry>
            <material name="silver" />
        </visual>
        <collision>
            <origin rpy="0 0 0" xyz="0 0 0" />
            <geometry>
                <mesh filename="package://ajgar/meshes/base_link.stl" scale="0.001 0.001 0.001" />
            </geometry>
        </collision>
    </link>
    <link name="base_top">
        <inertial>
            <origin rpy="0 0 0" xyz="3.830065892888174e-06 0.00017441579178078398 0.032466866299290215" />
            <mass value="1.2219948495058053" />
            <inertia ixx="0.001733" ixy="1e-06" ixz="1e-06" iyy="0.001362" iyz="2.5e-05" izz="0.001507" />
        </inertial>
        <visual>
            <origin rpy="0 0 0" xyz="0.020178 -0.052442 0.030236" />
            <geometry>
                <mesh filename="package://ajgar/meshes/base_top.stl" scale="0.001 0.001 0.001" />
            </geometry>
            <material name="silver" />
        </visual>
        <collision>
            <origin rpy="0 0 0" xyz="0.020178 -0.052442 0.030236" />
            <geometry>
                <mesh filename="package://ajgar/meshes/base_top.stl" scale="0.001 0.001 0.001" />
            </geometry>
        </collision>
    </link>
    <link name="shoulder">
        <inertial>
            <origin rpy="0 0 0" xyz="-5.719567535509423e-06 0.03029384656320288 0.10674064897096452" />
            <mass value="2.9743567366826063" />
            <inertia ixx="0.027269" ixy="1e-06" ixz="3e-06" iyy="0.027148" iyz="0.00023" izz="0.002649" />
        </inertial>
        <visual>
            <origin rpy="0 0 0" xyz="0.020178 -0.027442 -0.023264" />
            <geometry>
                <mesh filename="package://ajgar/meshes/shoulder.stl" scale="0.001 0.001 0.001" />
            </geometry>
            <material name="silver" />
        </visual>
        <collision>
            <origin rpy="0 0 0" xyz="0.020178 -0.027442 -0.023264" />
            <geometry>
                <mesh filename="package://ajgar/meshes/shoulder.stl" scale="0.001 0.001 0.001" />
            </geometry>
        </collision>
    </link>
    <link name="suction">
        <inertial>
            <origin rpy="0 0 0" xyz="0.0013549936256032208 0.03686493030435532 0.0010282342212279971" />
            <mass value="1.0937894888063466" />
            <inertia ixx="0.000604" ixy="-6e-06" ixz="2.3e-05" iyy="0.000571" iyz="-1e-06" izz="0.000737" />
        </inertial>
        <visual>
            <origin rpy="0 0 0" xyz="0.020178 -0.020442 -0.565785" />
            <geometry>
                <mesh filename="package://ajgar/meshes/suction.stl" scale="0.001 0.001 0.001" />
            </geometry>
            <material name="silver" />
        </visual>
        <collision>
            <origin rpy="0 0 0" xyz="0.020178 -0.020442 -0.565785" />
            <geometry>
                <mesh filename="package://ajgar/meshes/suction.stl" scale="0.001 0.001 0.001" />
            </geometry>
        </collision>
    </link>
    <link name="KINECT_XBOX">
        <inertial>
            <origin rpy="0 0 0" xyz="0.028613885036292752 4.6099368583032985e-05 -0.04112449528385209" />
            <mass value="5.170558909547441" />
            <inertia ixx="0.024426" ixy="-1e-06" ixz="1.9e-05" iyy="0.003279" iyz="8e-06" izz="0.024604" />
        </inertial>
        <visual>
            <origin rpy="0 0 0" xyz="-0.412541 -0.062924 -0.690764" />
            <geometry>
                <mesh filename="package://ajgar/meshes/KINECT_XBOX.stl" scale="0.001 0.001 0.001" />
            </geometry>
            <material name="silver" />
        </visual>
        <collision>
            <origin rpy="0 0 0" xyz="-0.412541 -0.062924 -0.690764" />
            <geometry>
                <mesh filename="package://ajgar/meshes/KINECT_XBOX.stl" scale="0.001 0.001 0.001" />
            </geometry>
        </collision>
    </link>
    <link name="wrist">
        <inertial>
            <origin rpy="0 0 0" xyz="0.0008460392490326658 0.00015737076862099714 0.016720215392772186" />
            <mass value="1.2638223022450714" />
            <inertia ixx="0.001154" ixy="-7e-06" ixz="1.3e-05" iyy="0.001222" iyz="-2e-06" izz="0.000623" />
        </inertial>
        <visual>
            <origin rpy="0 0 0" xyz="0.020178 -0.057442 -0.466264" />
            <geometry>
                <mesh filename="package://ajgar/meshes/wrist.stl" scale="0.001 0.001 0.001" />
            </geometry>
            <material name="silver" />
        </visual>
        <collision>
            <origin rpy="0 0 0" xyz="0.020178 -0.057442 -0.466264" />
            <geometry>
                <mesh filename="package://ajgar/meshes/wrist.stl" scale="0.001 0.001 0.001" />
            </geometry>
        </collision>
    </link>
    <link name="extrusion3">
        <inertial>
            <origin rpy="0 0 0" xyz="0.3055026196052988 -0.019854184601274943 0.5577019919988926" />
            <mass value="5.889005305436553" />
            <inertia ixx="1.15866" ixy="0.00111" ixz="0.000389" iyy="0.40406" iyz="-0.003566" izz="0.755642" />
        </inertial>
        <visual>
            <origin rpy="0 0 0" xyz="-0.116374 -0.085442 0.108605" />
            <geometry>
                <mesh filename="package://ajgar/meshes/extrusion3.stl" scale="0.001 0.001 0.001" />
            </geometry>
            <material name="silver" />
        </visual>
        <collision>
            <origin rpy="0 0 0" xyz="-0.116374 -0.085442 0.108605" />
            <geometry>
                <mesh filename="package://ajgar/meshes/extrusion3.stl" scale="0.001 0.001 0.001" />
            </geometry>
        </collision>
    </link>
    <link name="end">
        <inertial>
            <origin rpy="0 0 0" xyz="1.609165792771164e-05 -0.028280263486046658 0.034985781904597335" />
            <mass value="0.6717186078596652" />
            <inertia ixx="0.001219" ixy="2e-06" ixz="-2e-06" iyy="0.000367" iyz="0.00019" izz="0.00104" />
        </inertial>
        <visual>
            <origin rpy="0 0 0" xyz="0.020178 -0.057442 -0.520764" />
            <geometry>
                <mesh filename="package://ajgar/meshes/end.stl" scale="0.001 0.001 0.001" />
            </geometry>
            <material name="silver" />
        </visual>
        <collision>
            <origin rpy="0 0 0" xyz="0.020178 -0.057442 -0.520764" />
            <geometry>
                <mesh filename="package://ajgar/meshes/end.stl" scale="0.001 0.001 0.001" />
            </geometry>
        </collision>
    </link>
    <link name="elbow">
        <inertial>
            <origin rpy="0 0 0" xyz="2.650580281468584e-06 0.027722787961992977 0.033843906977580496" />
            <mass value="1.503376993994313" />
            <inertia ixx="0.004533" ixy="-0.0" ixz="-0.0" iyy="0.004824" iyz="2.3e-05" izz="0.001216" />
        </inertial>
        <visual>
            <origin rpy="0 0 0" xyz="0.020178 -0.032442 -0.261264" />
            <geometry>
                <mesh filename="package://ajgar/meshes/elbow.stl" scale="0.001 0.001 0.001" />
            </geometry>
            <material name="silver" />
        </visual>
        <collision>
            <origin rpy="0 0 0" xyz="0.020178 -0.032442 -0.261264" />
            <geometry>
                <mesh filename="package://ajgar/meshes/elbow.stl" scale="0.001 0.001 0.001" />
            </geometry>
        </collision>
    </link>
    <joint name="base_joint" type="continuous">
        <origin rpy="0 0 0" xyz="-0.020178 0.052442 -0.030236" />
        <parent link="base_link" />
        <child link="base_top" />
        <axis xyz="-0.0 -0.0 1.0" />
    </joint>
    <joint name="shoulder_joint" type="revolute">
        <origin rpy="0 0 0" xyz="0.0 -0.025 0.0535" />
        <parent link="base_top" />
        <child link="shoulder" />
        <axis xyz="-0.0 1.0 0.0" />
        <limit effort="100" lower="-1.570796" upper="1.570796" velocity="100" />
    </joint>
    <joint name="wrist_joint" type="fixed">
        <origin rpy="0 0 0" xyz="0.0 0.025 0.205" />
        <parent link="elbow" />
        <child link="wrist" />
    </joint>
    <joint name="elbow_joint" type="revolute">
        <origin rpy="0 0 0" xyz="0.0 0.005 0.238" />
        <parent link="shoulder" />
        <child link="elbow" />
        <axis xyz="-0.0 1.0 0.0" />
        <limit effort="100" lower="-2.443461" upper="2.443461" velocity="100" />
    </joint>
    <joint name="end_joint" type="continuous">
        <origin rpy="0 0 0" xyz="0.0 0.0 0.0545" />
        <parent link="wrist" />
        <child link="end" />
        <axis xyz="-0.0 -0.0 1.0" />
    </joint>
    <joint name="suction_joint" type="revolute">
        <origin rpy="0 0 0" xyz="0.0 -0.037 0.045021" />
        <parent link="end" />
        <child link="suction" />
        <axis xyz="0.0 -1.0 0.0" />
        <limit effort="100" lower="-0.698132" upper="2.443461" velocity="100" />
    </joint>
    <joint name="kinect_joint" type="fixed">
        <origin rpy="0 0 0" xyz="0.296167 -0.022518 0.799369" />
        <parent link="extrusion3" />
        <child link="KINECT_XBOX" />
    </joint>
    <joint name="extrusion_joint" type="fixed">
        <origin rpy="0 0 0" xyz="0.116374 0.085442 -0.108605" />
        <parent link="base_link" />
        <child link="extrusion3" />
    </joint>
</robot>

