<sdf version='1.7'>
  <world name='default'>
    <plugin name='ros_link_attacher_plugin' filename='libplugin_pneumatic_gripper.so'/>
    <plugin name='plugin_collision_publish' filename='libplugin_collision_publish.so'/>
    <light name='sun' type='directional'>
      <cast_shadows>1</cast_shadows>
      <pose>0 0 10 0 -0 0</pose>
      <diffuse>0.8 0.8 0.8 1</diffuse>
      <specular>0.2 0.2 0.2 1</specular>
      <attenuation>
        <range>1000</range>
        <constant>0.9</constant>
        <linear>0.01</linear>
        <quadratic>0.001</quadratic>
      </attenuation>
      <direction>-0.5 0.1 -0.9</direction>
      <spot>
        <inner_angle>0</inner_angle>
        <outer_angle>0</outer_angle>
        <falloff>0</falloff>
      </spot>
    </light>
    <model name='ground_plane'>
      <static>1</static>
      <link name='link'>
        <collision name='collision'>
          <geometry>
            <plane>
              <normal>0 0 1</normal>
              <size>100 100</size>
            </plane>
          </geometry>
          <surface>
            <friction>
              <ode>
                <mu>100</mu>
                <mu2>50</mu2>
              </ode>
              <torsional>
                <ode/>
              </torsional>
            </friction>
            <contact>
              <ode/>
            </contact>
            <bounce/>
          </surface>
          <max_contacts>10</max_contacts>
        </collision>
        <visual name='visual'>
          <cast_shadows>0</cast_shadows>
          <geometry>
            <plane>
              <normal>0 0 1</normal>
              <size>100 100</size>
            </plane>
          </geometry>
          <material>
            <script>
              <uri>file://media/materials/scripts/gazebo.material</uri>
              <name>Gazebo/Grey</name>
            </script>
          </material>
        </visual>
        <self_collide>0</self_collide>
        <enable_wind>1</enable_wind>
        <kinematic>0</kinematic>
      </link>
      <enable_wind>1</enable_wind>
    </model>
    <gravity>0 0 -9.8</gravity>
    <magnetic_field>6e-06 2.3e-05 -4.2e-05</magnetic_field>
    <atmosphere type='adiabatic'/>
    <physics type='ode'>
      <max_step_size>0.001</max_step_size>
      <real_time_factor>1</real_time_factor>
      <real_time_update_rate>1000</real_time_update_rate>
    </physics>
    <scene>
      <ambient>0.4 0.4 0.4 1</ambient>
      <background>0.7 0.7 0.7 1</background>
      <shadows>1</shadows>
    </scene>
    <wind/>
    <spherical_coordinates>
      <surface_model>EARTH_WGS84</surface_model>
      <latitude_deg>0</latitude_deg>
      <longitude_deg>0</longitude_deg>
      <elevation>0</elevation>
      <heading_deg>0</heading_deg>
    </spherical_coordinates>
    <state world_name='default'>
      <sim_time>1466 756000000</sim_time>
      <real_time>388 420304271</real_time>
      <wall_time>1700123413 929859516</wall_time>
      <iterations>221596</iterations>
      <model name='ajgar'>
        <pose>0.65 0 0 0 -0 0</pose>
        <scale>1 1 1</scale>
        <link name='base_link'>
          <pose>0.65 0 0 -0 -0 -3.14119</pose>
          <velocity>0 -0 0 0 -6e-06 0</velocity>
          <acceleration>-7.8e-05 2.1e-05 0.000372 -0.00158 -0.010703 0.00014</acceleration>
          <wrench>-0.000392 0.000106 0.001862 0 -0 0</wrench>
        </link>
        <link name='base_top'>
          <pose>0.649998 1e-06 0.049 -4e-06 5e-06 -1.0411</pose>
          <velocity>0 -0 0 -1e-06 -4e-06 -2.7e-05</velocity>
          <acceleration>-7.5e-05 2e-06 0.000286 -0.002432 -0.00621 -0.000533</acceleration>
          <wrench>-3.4e-05 1e-06 0.000128 0 -0 0</wrench>
        </link>
        <link name='elbow'>
          <pose>0.671828 0.018126 0.453478 1.3e-05 -2.3e-05 -1.0411</pose>
          <velocity>-0.000557 0.000952 2e-06 -0.003443 -0.002016 -2.7e-05</velocity>
          <acceleration>-0 8e-06 2e-06 -0.000106 -7.8e-05 -4.2e-05</acceleration>
          <wrench>-1e-06 1.9e-05 5e-06 0 -0 0</wrench>
        </link>
        <link name='end'>
          <pose>0.64766 0.00398 0.722977 1.5e-05 6.9e-05 -1.0411</pose>
          <velocity>-0.001114 0.001902 2e-06 -0.004335 -0.002538 -8e-06</velocity>
          <acceleration>-2.8e-05 3.7e-05 1e-06 -0.000224 -0.000118 -3e-05</acceleration>
          <wrench>-2e-06 3e-06 0 0 -0 0</wrench>
        </link>
        <link name='shoulder'>
          <pose>0.621583 -0.010842 0.174626 1.3e-05 -5.7e-05 -1.0411</pose>
          <velocity>-0 1e-06 0 -0.003416 -0.002 -2.7e-05</velocity>
          <acceleration>1.6e-05 -1.4e-05 3e-06 -0.000115 -7.3e-05 -5.1e-05</acceleration>
          <wrench>8.1e-05 -6.7e-05 1.4e-05 0 -0 0</wrench>
        </link>
        <link name='suction'>
          <pose>0.61573 -0.014713 0.698476 1.6e-05 6.8e-05 -1.0411</pose>
          <velocity>-0.001052 0.001797 2e-06 -0.004335 -0.002538 -2.3e-05</velocity>
          <acceleration>-2.2e-05 3.2e-05 2e-06 -0.000195 -0.000131 -3.2e-05</acceleration>
          <wrench>-1.3e-05 1.9e-05 1e-06 0 -0 0</wrench>
        </link>
        <link name='wrist'>
          <pose>0.647661 0.003981 0.653477 1.3e-05 -2.3e-05 -1.0411</pose>
          <velocity>-0.000961 0.001641 2e-06 -0.003443 -0.002016 -2.3e-05</velocity>
          <acceleration>-1.7e-05 2.7e-05 4e-06 -0.000221 -0.000148 4e-06</acceleration>
          <wrench>-6e-06 9e-06 1e-06 0 -0 0</wrench>
        </link>
      </model>
      <model name='ground_plane'>
        <pose>0 0 0 0 -0 0</pose>
        <scale>1 1 1</scale>
        <link name='link'>
          <pose>0 0 0 0 -0 0</pose>
          <velocity>0 0 0 0 -0 0</velocity>
          <acceleration>0 0 0 0 -0 0</acceleration>
          <wrench>0 0 0 0 -0 0</wrench>
        </link>
      </model>
      <model name='medium_box_1_clone_0'>
        <pose>0.048478 -0.345938 0.110045 -0.00014 -5e-06 -0.284083</pose>
        <scale>1 1 1</scale>
        <link name='link'>
          <pose>0.048478 -0.345938 0.110045 -0.00014 -5e-06 -0.284083</pose>
          <velocity>0 0 0 0 -0 0</velocity>
          <acceleration>-0.356802 0.108956 -0.005181 2.1515 0.100083 -3.14104</acceleration>
          <wrench>-0.356802 0.108956 -0.005181 0 -0 0</wrench>
        </link>
      </model>
      <model name='small_box_1_clone'>
        <pose>0.261055 0.035758 0.019538 -3.14159 -1e-06 -0.470367</pose>
        <scale>1 1 1</scale>
        <link name='link'>
          <pose>0.261055 0.035758 0.019538 -3.14159 -1e-06 -0.470367</pose>
          <velocity>0 0 0 0 -0 0</velocity>
          <acceleration>-0.007649 -0.009023 -0.008033 0.461787 -0.391502 1e-06</acceleration>
          <wrench>-0.005508 -0.006496 -0.005784 0 -0 0</wrench>
        </link>
      </model>
      <model name='small_box_1_clone_0'>
        <pose>0.470145 -0.120877 0.019538 3.14159 -1e-06 -1.93521</pose>
        <scale>1 1 1</scale>
        <link name='link'>
          <pose>0.470145 -0.120877 0.019538 3.14159 -1e-06 -1.93521</pose>
          <velocity>0 0 0 0 -0 0</velocity>
          <acceleration>0.010181 -0.005809 -0.003838 0.297327 0.521055 -1e-06</acceleration>
          <wrench>0.00733 -0.004183 -0.002764 0 -0 0</wrench>
        </link>
      </model>
      <model name='small_box_1_clone_1'>
        <pose>0.377407 0.081435 0.057717 1.5708 -1e-06 -0.845915</pose>
        <scale>1 1 1</scale>
        <link name='link'>
          <pose>0.377407 0.081435 0.057717 1.5708 -1e-06 -0.845915</pose>
          <velocity>0 0 0 0 -0 0</velocity>
          <acceleration>-0 0 -0 -0 -0 -0</acceleration>
          <wrench>-0 0 -0 0 -0 0</wrench>
        </link>
      </model>
      <model name='small_box_1_clone_2'>
        <pose>0.350962 -0.159195 0.043882 -1.57081 -3e-06 -1.66671</pose>
        <scale>1 1 1</scale>
        <link name='link'>
          <pose>0.350962 -0.159195 0.043882 -1.57081 -3e-06 -1.66671</pose>
          <velocity>0 0 0 0 -0 0</velocity>
          <acceleration>-0 0 -0 0 -0 0</acceleration>
          <wrench>-0 0 -0 0 -0 0</wrench>
        </link>
      </model>
      <light name='sun'>
        <pose>0 0 10 0 -0 0</pose>
      </light>
      <light name='user_directional_light_0'>
        <pose>9.22363 9.30195 1 0 -0 0</pose>
      </light>
      <light name='user_directional_light_1'>
        <pose>9.14809 -9.33168 1 0 -0 0</pose>
      </light>
      <light name='user_directional_light_2'>
        <pose>-9.37298 9.38045 1 0 -0 0</pose>
      </light>
      <light name='user_directional_light_3'>
        <pose>-9.57927 -9.54885 1 0 -0 0</pose>
      </light>
      <light name='user_directional_light_4'>
        <pose>0.072583 9.49417 1 0 -0 0</pose>
      </light>
      <light name='user_directional_light_5'>
        <pose>-0.277591 -9.80792 1 0 -0 0</pose>
      </light>
    </state>
    <gui fullscreen='0'>
      <camera name='user_camera'>
        <pose>0.650929 -3.91115 3.09453 0 0.673876 1.2824</pose>
        <view_controller>orbit</view_controller>
        <projection_type>perspective</projection_type>
      </camera>
    </gui>
    <light name='user_directional_light_0' type='directional'>
      <pose>9.22363 9.30195 1 0 -0 0</pose>
      <diffuse>0.5 0.5 0.5 1</diffuse>
      <specular>0.1 0.1 0.1 1</specular>
      <direction>0.1 0.1 -0.9</direction>
      <attenuation>
        <range>20</range>
        <constant>0.5</constant>
        <linear>0.01</linear>
        <quadratic>0.001</quadratic>
      </attenuation>
      <cast_shadows>1</cast_shadows>
      <spot>
        <inner_angle>0</inner_angle>
        <outer_angle>0</outer_angle>
        <falloff>0</falloff>
      </spot>
    </light>
    <light name='user_directional_light_1' type='directional'>
      <pose>9.14809 -9.33168 1 0 -0 0</pose>
      <diffuse>0.5 0.5 0.5 1</diffuse>
      <specular>0.1 0.1 0.1 1</specular>
      <direction>0.1 0.1 -0.9</direction>
      <attenuation>
        <range>20</range>
        <constant>0.5</constant>
        <linear>0.01</linear>
        <quadratic>0.001</quadratic>
      </attenuation>
      <cast_shadows>1</cast_shadows>
      <spot>
        <inner_angle>0</inner_angle>
        <outer_angle>0</outer_angle>
        <falloff>0</falloff>
      </spot>
    </light>
    <light name='user_directional_light_2' type='directional'>
      <pose>-9.37298 9.38045 1 0 -0 0</pose>
      <diffuse>0.5 0.5 0.5 1</diffuse>
      <specular>0.1 0.1 0.1 1</specular>
      <direction>0.1 0.1 -0.9</direction>
      <attenuation>
        <range>20</range>
        <constant>0.5</constant>
        <linear>0.01</linear>
        <quadratic>0.001</quadratic>
      </attenuation>
      <cast_shadows>1</cast_shadows>
      <spot>
        <inner_angle>0</inner_angle>
        <outer_angle>0</outer_angle>
        <falloff>0</falloff>
      </spot>
    </light>
    <light name='user_directional_light_3' type='directional'>
      <pose>-9.57927 -9.54885 1 0 -0 0</pose>
      <diffuse>0.5 0.5 0.5 1</diffuse>
      <specular>0.1 0.1 0.1 1</specular>
      <direction>0.1 0.1 -0.9</direction>
      <attenuation>
        <range>20</range>
        <constant>0.5</constant>
        <linear>0.01</linear>
        <quadratic>0.001</quadratic>
      </attenuation>
      <cast_shadows>1</cast_shadows>
      <spot>
        <inner_angle>0</inner_angle>
        <outer_angle>0</outer_angle>
        <falloff>0</falloff>
      </spot>
    </light>
    <model name='medium_box_1_clone_0'>
      <link name='link'>
        <inertial>
          <mass>1</mass>
          <inertia>
            <ixy>0</ixy>
            <ixz>0</ixz>
            <iyz>0</iyz>
            <ixx>0.05288</ixx>
            <iyy>0.05288</iyy>
            <izz>0.09132</izz>
          </inertia>
          <pose>0 0 0 0 -0 0</pose>
        </inertial>
        <self_collide>0</self_collide>
        <enable_wind>0</enable_wind>
        <kinematic>0</kinematic>
        <pose>0 0 0 0 -0 0</pose>
        <gravity>1</gravity>
        <visual name='visual'>
          <geometry>
            <mesh>
              <uri>model://medium_boxes/meshes/medium_box.dae</uri>
              <scale>1 1 1</scale>
            </mesh>
          </geometry>
          <meta>
            <layer>1</layer>
          </meta>
          <material>
            <shader type='pixel'>
              <normal_map>__default__</normal_map>
            </shader>
          </material>
          <pose>0 0 0 0 -0 0</pose>
          <transparency>0</transparency>
          <cast_shadows>1</cast_shadows>
        </visual>
        <collision name='collision'>
          <laser_retro>0</laser_retro>
          <max_contacts>10</max_contacts>
          <pose>0 0 0 0 -0 0</pose>
          <geometry>
            <mesh>
              <uri>model://medium_boxes/meshes/medium_box.dae</uri>
              <scale>1 1 1</scale>
            </mesh>
          </geometry>
          <surface>
            <friction>
              <ode>
                <mu>1</mu>
                <mu2>1</mu2>
                <fdir1>0 0 0</fdir1>
                <slip1>0</slip1>
                <slip2>0</slip2>
              </ode>
              <torsional>
                <coefficient>1</coefficient>
                <patch_radius>0</patch_radius>
                <surface_radius>0</surface_radius>
                <use_patch_radius>1</use_patch_radius>
                <ode>
                  <slip>0</slip>
                </ode>
              </torsional>
            </friction>
            <bounce>
              <restitution_coefficient>0</restitution_coefficient>
              <threshold>0</threshold>
            </bounce>
            <contact>
              <collide_without_contact>0</collide_without_contact>
              <collide_without_contact_bitmask>1</collide_without_contact_bitmask>
              <collide_bitmask>1</collide_bitmask>
              <ode>
                <soft_cfm>0</soft_cfm>
                <soft_erp>0.2</soft_erp>
                <kp>100000</kp>
                <kd>1</kd>
                <max_vel>0.001</max_vel>
                <min_depth>0</min_depth>
              </ode>
              <bullet>
                <split_impulse>1</split_impulse>
                <split_impulse_penetration_threshold>-0.01</split_impulse_penetration_threshold>
                <soft_cfm>0</soft_cfm>
                <soft_erp>0.2</soft_erp>
                <kp>100000</kp>
                <kd>1</kd>
              </bullet>
            </contact>
          </surface>
        </collision>
      </link>
      <static>0</static>
      <allow_auto_disable>1</allow_auto_disable>
      <pose>-0.008453 -1.28806 0.111931 -0.001169 -0.000148 2.3e-05</pose>
    </model>
    <model name='small_box_1_clone'>
      <link name='link'>
        <inertial>
          <mass>0.72</mass>
          <inertia>
            <ixy>0</ixy>
            <ixz>0</ixz>
            <iyz>0</iyz>
            <ixx>0.05288</ixx>
            <iyy>0.05288</iyy>
            <izz>0.09132</izz>
          </inertia>
          <pose>0 0 0 0 -0 0</pose>
        </inertial>
        <self_collide>0</self_collide>
        <enable_wind>0</enable_wind>
        <kinematic>0</kinematic>
        <pose>0 0 0 0 -0 0</pose>
        <gravity>1</gravity>
        <visual name='visual'>
          <geometry>
            <mesh>
              <uri>model://small_boxes/meshes/small_box.dae</uri>
              <scale>1 1 1</scale>
            </mesh>
          </geometry>
          <meta>
            <layer>1</layer>
          </meta>
          <material>
            <shader type='pixel'>
              <normal_map>__default__</normal_map>
            </shader>
          </material>
          <pose>0 0 0 0 -0 0</pose>
          <transparency>0</transparency>
          <cast_shadows>1</cast_shadows>
        </visual>
        <collision name='collision'>
          <laser_retro>0</laser_retro>
          <max_contacts>10</max_contacts>
          <pose>0 0 0 0 -0 0</pose>
          <geometry>
            <mesh>
              <uri>model://small_boxes/meshes/small_box.dae</uri>
              <scale>1 1 1</scale>
            </mesh>
          </geometry>
          <surface>
            <friction>
              <ode>
                <mu>1000</mu>
                <mu2>1000</mu2>
                <fdir1>0 0 0</fdir1>
                <slip1>0</slip1>
                <slip2>0</slip2>
              </ode>
              <torsional>
                <coefficient>1</coefficient>
                <patch_radius>0</patch_radius>
                <surface_radius>0</surface_radius>
                <use_patch_radius>1</use_patch_radius>
                <ode>
                  <slip>0</slip>
                </ode>
              </torsional>
            </friction>
            <bounce>
              <restitution_coefficient>0</restitution_coefficient>
              <threshold>0</threshold>
            </bounce>
            <contact>
              <collide_without_contact>0</collide_without_contact>
              <collide_without_contact_bitmask>1</collide_without_contact_bitmask>
              <collide_bitmask>1</collide_bitmask>
              <ode>
                <soft_cfm>0</soft_cfm>
                <soft_erp>0.2</soft_erp>
                <kp>1e+06</kp>
                <kd>1</kd>
                <max_vel>0.01</max_vel>
                <min_depth>0</min_depth>
              </ode>
              <bullet>
                <split_impulse>1</split_impulse>
                <split_impulse_penetration_threshold>-0.01</split_impulse_penetration_threshold>
                <soft_cfm>0</soft_cfm>
                <soft_erp>0.2</soft_erp>
                <kp>1e+06</kp>
                <kd>1</kd>
              </bullet>
            </contact>
          </surface>
        </collision>
      </link>
      <static>0</static>
      <allow_auto_disable>1</allow_auto_disable>
      <pose>-0.415508 0.132982 0.043961 0 -3e-06 1.7e-05</pose>
    </model>
    <model name='small_box_1_clone_0'>
      <link name='link'>
        <inertial>
          <mass>0.72</mass>
          <inertia>
            <ixy>0</ixy>
            <ixz>0</ixz>
            <iyz>0</iyz>
            <ixx>0.05288</ixx>
            <iyy>0.05288</iyy>
            <izz>0.09132</izz>
          </inertia>
          <pose>0 0 0 0 -0 0</pose>
        </inertial>
        <self_collide>0</self_collide>
        <enable_wind>0</enable_wind>
        <kinematic>0</kinematic>
        <pose>0 0 0 0 -0 0</pose>
        <gravity>1</gravity>
        <visual name='visual'>
          <geometry>
            <mesh>
              <uri>model://small_boxes/meshes/small_box.dae</uri>
              <scale>1 1 1</scale>
            </mesh>
          </geometry>
          <meta>
            <layer>1</layer>
          </meta>
          <material>
            <shader type='pixel'>
              <normal_map>__default__</normal_map>
            </shader>
          </material>
          <pose>0 0 0 0 -0 0</pose>
          <transparency>0</transparency>
          <cast_shadows>1</cast_shadows>
        </visual>
        <collision name='collision'>
          <laser_retro>0</laser_retro>
          <max_contacts>10</max_contacts>
          <pose>0 0 0 0 -0 0</pose>
          <geometry>
            <mesh>
              <uri>model://small_boxes/meshes/small_box.dae</uri>
              <scale>1 1 1</scale>
            </mesh>
          </geometry>
          <surface>
            <friction>
              <ode>
                <mu>1000</mu>
                <mu2>1000</mu2>
                <fdir1>0 0 0</fdir1>
                <slip1>0</slip1>
                <slip2>0</slip2>
              </ode>
              <torsional>
                <coefficient>1</coefficient>
                <patch_radius>0</patch_radius>
                <surface_radius>0</surface_radius>
                <use_patch_radius>1</use_patch_radius>
                <ode>
                  <slip>0</slip>
                </ode>
              </torsional>
            </friction>
            <bounce>
              <restitution_coefficient>0</restitution_coefficient>
              <threshold>0</threshold>
            </bounce>
            <contact>
              <collide_without_contact>0</collide_without_contact>
              <collide_without_contact_bitmask>1</collide_without_contact_bitmask>
              <collide_bitmask>1</collide_bitmask>
              <ode>
                <soft_cfm>0</soft_cfm>
                <soft_erp>0.2</soft_erp>
                <kp>1e+06</kp>
                <kd>1</kd>
                <max_vel>0.01</max_vel>
                <min_depth>0</min_depth>
              </ode>
              <bullet>
                <split_impulse>1</split_impulse>
                <split_impulse_penetration_threshold>-0.01</split_impulse_penetration_threshold>
                <soft_cfm>0</soft_cfm>
                <soft_erp>0.2</soft_erp>
                <kp>1e+06</kp>
                <kd>1</kd>
              </bullet>
            </contact>
          </surface>
        </collision>
      </link>
      <static>0</static>
      <allow_auto_disable>1</allow_auto_disable>
      <pose>-0.411873 -0.050107 0.043961 0 -3e-06 1.7e-05</pose>
    </model>
    <model name='small_box_1_clone_1'>
      <link name='link'>
        <inertial>
          <mass>0.72</mass>
          <inertia>
            <ixy>0</ixy>
            <ixz>0</ixz>
            <iyz>0</iyz>
            <ixx>0.05288</ixx>
            <iyy>0.05288</iyy>
            <izz>0.09132</izz>
          </inertia>
          <pose>0 0 0 0 -0 0</pose>
        </inertial>
        <self_collide>0</self_collide>
        <enable_wind>0</enable_wind>
        <kinematic>0</kinematic>
        <pose>0 0 0 0 -0 0</pose>
        <gravity>1</gravity>
        <visual name='visual'>
          <geometry>
            <mesh>
              <uri>model://small_boxes/meshes/small_box.dae</uri>
              <scale>1 1 1</scale>
            </mesh>
          </geometry>
          <meta>
            <layer>1</layer>
          </meta>
          <material>
            <shader type='pixel'>
              <normal_map>__default__</normal_map>
            </shader>
          </material>
          <pose>0 0 0 0 -0 0</pose>
          <transparency>0</transparency>
          <cast_shadows>1</cast_shadows>
        </visual>
        <collision name='collision'>
          <laser_retro>0</laser_retro>
          <max_contacts>10</max_contacts>
          <pose>0 0 0 0 -0 0</pose>
          <geometry>
            <mesh>
              <uri>model://small_boxes/meshes/small_box.dae</uri>
              <scale>1 1 1</scale>
            </mesh>
          </geometry>
          <surface>
            <friction>
              <ode>
                <mu>1000</mu>
                <mu2>1000</mu2>
                <fdir1>0 0 0</fdir1>
                <slip1>0</slip1>
                <slip2>0</slip2>
              </ode>
              <torsional>
                <coefficient>1</coefficient>
                <patch_radius>0</patch_radius>
                <surface_radius>0</surface_radius>
                <use_patch_radius>1</use_patch_radius>
                <ode>
                  <slip>0</slip>
                </ode>
              </torsional>
            </friction>
            <bounce>
              <restitution_coefficient>0</restitution_coefficient>
              <threshold>0</threshold>
            </bounce>
            <contact>
              <collide_without_contact>0</collide_without_contact>
              <collide_without_contact_bitmask>1</collide_without_contact_bitmask>
              <collide_bitmask>1</collide_bitmask>
              <ode>
                <soft_cfm>0</soft_cfm>
                <soft_erp>0.2</soft_erp>
                <kp>1e+06</kp>
                <kd>1</kd>
                <max_vel>0.01</max_vel>
                <min_depth>0</min_depth>
              </ode>
              <bullet>
                <split_impulse>1</split_impulse>
                <split_impulse_penetration_threshold>-0.01</split_impulse_penetration_threshold>
                <soft_cfm>0</soft_cfm>
                <soft_erp>0.2</soft_erp>
                <kp>1e+06</kp>
                <kd>1</kd>
              </bullet>
            </contact>
          </surface>
        </collision>
      </link>
      <static>0</static>
      <allow_auto_disable>1</allow_auto_disable>
      <pose>-0.408371 -0.306355 0.043961 0 -3e-06 1.7e-05</pose>
    </model>
    <model name='small_box_1_clone_2'>
      <link name='link'>
        <inertial>
          <mass>0.72</mass>
          <inertia>
            <ixy>0</ixy>
            <ixz>0</ixz>
            <iyz>0</iyz>
            <ixx>0.05288</ixx>
            <iyy>0.05288</iyy>
            <izz>0.09132</izz>
          </inertia>
          <pose>0 0 0 0 -0 0</pose>
        </inertial>
        <self_collide>0</self_collide>
        <enable_wind>0</enable_wind>
        <kinematic>0</kinematic>
        <pose>0 0 0 0 -0 0</pose>
        <gravity>1</gravity>
        <visual name='visual'>
          <geometry>
            <mesh>
              <uri>model://small_boxes/meshes/small_box.dae</uri>
              <scale>1 1 1</scale>
            </mesh>
          </geometry>
          <meta>
            <layer>1</layer>
          </meta>
          <material>
            <shader type='pixel'>
              <normal_map>__default__</normal_map>
            </shader>
          </material>
          <pose>0 0 0 0 -0 0</pose>
          <transparency>0</transparency>
          <cast_shadows>1</cast_shadows>
        </visual>
        <collision name='collision'>
          <laser_retro>0</laser_retro>
          <max_contacts>10</max_contacts>
          <pose>0 0 0 0 -0 0</pose>
          <geometry>
            <mesh>
              <uri>model://small_boxes/meshes/small_box.dae</uri>
              <scale>1 1 1</scale>
            </mesh>
          </geometry>
          <surface>
            <friction>
              <ode>
                <mu>1000</mu>
                <mu2>1000</mu2>
                <fdir1>0 0 0</fdir1>
                <slip1>0</slip1>
                <slip2>0</slip2>
              </ode>
              <torsional>
                <coefficient>1</coefficient>
                <patch_radius>0</patch_radius>
                <surface_radius>0</surface_radius>
                <use_patch_radius>1</use_patch_radius>
                <ode>
                  <slip>0</slip>
                </ode>
              </torsional>
            </friction>
            <bounce>
              <restitution_coefficient>0</restitution_coefficient>
              <threshold>0</threshold>
            </bounce>
            <contact>
              <collide_without_contact>0</collide_without_contact>
              <collide_without_contact_bitmask>1</collide_without_contact_bitmask>
              <collide_bitmask>1</collide_bitmask>
              <ode>
                <soft_cfm>0</soft_cfm>
                <soft_erp>0.2</soft_erp>
                <kp>1e+06</kp>
                <kd>1</kd>
                <max_vel>0.01</max_vel>
                <min_depth>0</min_depth>
              </ode>
              <bullet>
                <split_impulse>1</split_impulse>
                <split_impulse_penetration_threshold>-0.01</split_impulse_penetration_threshold>
                <soft_cfm>0</soft_cfm>
                <soft_erp>0.2</soft_erp>
                <kp>1e+06</kp>
                <kd>1</kd>
              </bullet>
            </contact>
          </surface>
        </collision>
      </link>
      <static>0</static>
      <allow_auto_disable>1</allow_auto_disable>
      <pose>-0.401262 -0.485138 0.043961 0 -3e-06 1.7e-05</pose>
    </model>
    <light name='user_directional_light_4' type='directional'>
      <pose>0.072583 9.49417 1 0 -0 0</pose>
      <diffuse>0.5 0.5 0.5 1</diffuse>
      <specular>0.1 0.1 0.1 1</specular>
      <direction>0.1 0.1 -0.9</direction>
      <attenuation>
        <range>20</range>
        <constant>0.5</constant>
        <linear>0.01</linear>
        <quadratic>0.001</quadratic>
      </attenuation>
      <cast_shadows>1</cast_shadows>
      <spot>
        <inner_angle>0</inner_angle>
        <outer_angle>0</outer_angle>
        <falloff>0</falloff>
      </spot>
    </light>
    <light name='user_directional_light_5' type='directional'>
      <pose>-0.277591 -9.80792 1 0 -0 0</pose>
      <diffuse>0.5 0.5 0.5 1</diffuse>
      <specular>0.1 0.1 0.1 1</specular>
      <direction>0.1 0.1 -0.9</direction>
      <attenuation>
        <range>20</range>
        <constant>0.5</constant>
        <linear>0.01</linear>
        <quadratic>0.001</quadratic>
      </attenuation>
      <cast_shadows>1</cast_shadows>
      <spot>
        <inner_angle>0</inner_angle>
        <outer_angle>0</outer_angle>
        <falloff>0</falloff>
      </spot>
    </light>
    <model name='ajgar'>
      <joint name='world_joint' type='fixed'>
        <pose relative_to='__model__'>0 0 0 0 0 -3.14119</pose>
        <parent>world</parent>
        <child>base_link</child>
      </joint>
      <link name='base_link'>
        <pose relative_to='world_joint'>0 0 0 0 -0 0</pose>
        <inertial>
          <pose>0.010105 -0 0.023181 0 -0 0</pose>
          <mass>5.00455</mass>
          <inertia>
            <ixx>0.013929</ixx>
            <ixy>9.02843e-07</ixy>
            <ixz>-8.88891e-06</ixz>
            <iyy>0.0182044</iyy>
            <iyz>2.21523e-06</iyz>
            <izz>0.0290188</izz>
          </inertia>
        </inertial>
        <collision name='base_link_collision'>
          <pose>0 0 0 0 -0 0</pose>
          <geometry>
            <mesh>
              <scale>0.001 0.001 0.001</scale>
              <uri>/home/jc/flipkartGrid_ws/src/flipkartGrid/ajgar_description/meshes/base_link.stl</uri>
            </mesh>
          </geometry>
          <surface>
            <contact>
              <ode/>
            </contact>
            <friction>
              <ode>
                <mu>0.2</mu>
                <mu2>0.2</mu2>
              </ode>
              <torsional>
                <ode/>
              </torsional>
            </friction>
            <bounce/>
          </surface>
          <max_contacts>10</max_contacts>
        </collision>
        <collision name='base_link_fixed_joint_lump__camera_depth_frame_collision_1'>
          <pose>0.612 -0.15 1.5 -1.57079 1.57079 3.14159</pose>
          <geometry>
            <mesh>
              <scale>0.005 0.005 0.005</scale>
              <uri>/home/jc/flipkartGrid_ws/src/flipkartGrid/ur5_description/meshes/kinect.stl</uri>
            </mesh>
          </geometry>
          <surface>
            <contact>
              <ode/>
            </contact>
            <friction>
              <ode/>
              <torsional>
                <ode/>
              </torsional>
            </friction>
            <bounce/>
          </surface>
          <max_contacts>10</max_contacts>
        </collision>
        <visual name='base_link_visual'>
          <pose>0 0 0 0 -0 0</pose>
          <geometry>
            <mesh>
              <scale>0.001 0.001 0.001</scale>
              <uri>/home/jc/flipkartGrid_ws/src/flipkartGrid/ajgar_description/meshes/base_link.stl</uri>
            </mesh>
          </geometry>
          <material>
            <script>
              <name>Gazebo/Silver</name>
              <uri>file://media/materials/scripts/gazebo.material</uri>
            </script>
          </material>
        </visual>
        <visual name='base_link_fixed_joint_lump__camera_depth_frame_visual_1'>
          <pose>0.612 -0.15 1.5 1.57 -0 0</pose>
          <geometry>
            <mesh>
              <scale>0.005 0.005 0.005</scale>
              <uri>/home/jc/flipkartGrid_ws/src/flipkartGrid/ur5_description/meshes/kinect.stl</uri>
            </mesh>
          </geometry>
        </visual>
        <self_collide>1</self_collide>
        <gravity>1</gravity>
        <sensor name='cm2' type='depth'>
          <update_rate>20</update_rate>
          <camera>
            <horizontal_fov>1.0472</horizontal_fov>
            <image>
              <width>640</width>
              <height>480</height>
              <format>R8G8B8</format>
            </image>
            <clip>
              <near>0.05</near>
              <far>3</far>
            </clip>
          </camera>
          <plugin name='depth_link_controller' filename='libgazebo_ros_openni_kinect.so'>
            <baseline>0.2</baseline>
            <alwaysOn>1</alwaysOn>
            <updateRate>1.0</updateRate>
            <cameraName>kinect_ir</cameraName>
            <imageTopicName>/kinect/color/image_raw</imageTopicName>
            <cameraInfoTopicName>/kinect/color/camera_info</cameraInfoTopicName>
            <depthImageTopicName>/kinect/depth/image_raw</depthImageTopicName>
            <depthImageInfoTopicName>/kinect/depth/camera_info</depthImageInfoTopicName>
            <pointCloudTopicName>/kinect/depth/points</pointCloudTopicName>
            <frameName>camera_depth_optical_frame</frameName>
            <pointCloudCutoff>0.5</pointCloudCutoff>
            <pointCloudCutoffMax>3.0</pointCloudCutoffMax>
            <distortionK1>0.00000001</distortionK1>
            <distortionK2>0.00000001</distortionK2>
            <distortionK3>0.00000001</distortionK3>
            <distortionT1>0.00000001</distortionT1>
            <distortionT2>0.00000001</distortionT2>
            <CxPrime>0</CxPrime>
            <Cx>0</Cx>
            <Cy>0</Cy>
            <focalLength>0</focalLength>
            <hackBaseline>0</hackBaseline>
            <robotNamespace>/</robotNamespace>
          </plugin>
          <pose>0.612 -0.15 1.5 3.14159 1.57079 3.14159</pose>
        </sensor>
        <enable_wind>0</enable_wind>
        <kinematic>0</kinematic>
      </link>
      <joint name='base' type='revolute'>
        <pose relative_to='base_link'>0 0 0.049 0 -0 0</pose>
        <parent>base_link</parent>
        <child>base_top</child>
        <axis>
          <xyz>0 0 1</xyz>
          <limit>
            <lower>-2.87979</lower>
            <upper>2.87979</upper>
            <effort>100</effort>
            <velocity>100</velocity>
          </limit>
          <dynamics>
            <spring_reference>0</spring_reference>
            <spring_stiffness>0</spring_stiffness>
          </dynamics>
        </axis>
      </joint>
      <link name='base_top'>
        <pose relative_to='base'>0 0 0 0 -0 0</pose>
        <inertial>
          <pose>0.000408 -0.00154 0.055522 0 -0 0</pose>
          <mass>0.446819</mass>
          <inertia>
            <ixx>0.00111</ixx>
            <ixy>-6e-06</ixy>
            <ixz>3.9e-05</ixz>
            <iyy>0.000992</iyy>
            <iyz>4.9e-05</iyz>
            <izz>0.00053</izz>
          </inertia>
        </inertial>
        <collision name='base_top_collision'>
          <pose>0 0 -0.049 0 -0 0</pose>
          <geometry>
            <mesh>
              <scale>0.001 0.001 0.001</scale>
              <uri>/home/jc/flipkartGrid_ws/src/flipkartGrid/ajgar_description/meshes/base_top.stl</uri>
            </mesh>
          </geometry>
          <surface>
            <contact>
              <ode/>
            </contact>
            <friction>
              <ode>
                <mu>0.2</mu>
                <mu2>0.2</mu2>
              </ode>
              <torsional>
                <ode/>
              </torsional>
            </friction>
            <bounce/>
          </surface>
          <max_contacts>10</max_contacts>
        </collision>
        <visual name='base_top_visual'>
          <pose>0 0 -0.049 0 -0 0</pose>
          <geometry>
            <mesh>
              <scale>0.001 0.001 0.001</scale>
              <uri>/home/jc/flipkartGrid_ws/src/flipkartGrid/ajgar_description/meshes/base_top.stl</uri>
            </mesh>
          </geometry>
          <material>
            <script>
              <name>Gazebo/Silver</name>
              <uri>file://media/materials/scripts/gazebo.material</uri>
            </script>
          </material>
        </visual>
        <self_collide>1</self_collide>
        <enable_wind>0</enable_wind>
        <kinematic>0</kinematic>
      </link>
      <joint name='shoulder_joint' type='revolute'>
        <pose relative_to='base_top'>-0.005001 -0.03 0.125627 0 -0 0</pose>
        <parent>base_top</parent>
        <child>shoulder</child>
        <axis>
          <xyz>0 1 0</xyz>
          <limit>
            <lower>-2.87979</lower>
            <upper>2.87979</upper>
            <effort>100</effort>
            <velocity>100</velocity>
          </limit>
          <dynamics>
            <spring_reference>0</spring_reference>
            <spring_stiffness>0</spring_stiffness>
          </dynamics>
        </axis>
      </joint>
      <link name='shoulder'>
        <pose relative_to='shoulder_joint'>0 0 0 0 -0 0</pose>
        <inertial>
          <pose>9.4e-05 0.031353 0.161728 0 -0 0</pose>
          <mass>4.91978</mass>
          <inertia>
            <ixx>0.043238</ixx>
            <ixy>-9e-06</ixy>
            <ixz>-3.7e-05</ixz>
            <iyy>0.042205</iyy>
            <iyz>-0.001721</iyz>
            <izz>0.00519</izz>
          </inertia>
        </inertial>
        <collision name='shoulder_collision'>
          <pose>0.005001 0.03 -0.174627 0 -0 0</pose>
          <geometry>
            <mesh>
              <scale>0.001 0.001 0.001</scale>
              <uri>/home/jc/flipkartGrid_ws/src/flipkartGrid/ajgar_description/meshes/shoulder.stl</uri>
            </mesh>
          </geometry>
          <surface>
            <contact>
              <ode/>
            </contact>
            <friction>
              <ode>
                <mu>0.2</mu>
                <mu2>0.2</mu2>
              </ode>
              <torsional>
                <ode/>
              </torsional>
            </friction>
            <bounce/>
          </surface>
          <max_contacts>10</max_contacts>
        </collision>
        <visual name='shoulder_visual'>
          <pose>0.005001 0.03 -0.174627 0 -0 0</pose>
          <geometry>
            <mesh>
              <scale>0.001 0.001 0.001</scale>
              <uri>/home/jc/flipkartGrid_ws/src/flipkartGrid/ajgar_description/meshes/shoulder.stl</uri>
            </mesh>
          </geometry>
          <material>
            <script>
              <name>Gazebo/Silver</name>
              <uri>file://media/materials/scripts/gazebo.material</uri>
            </script>
          </material>
        </visual>
        <self_collide>1</self_collide>
        <enable_wind>0</enable_wind>
        <kinematic>0</kinematic>
      </link>
      <joint name='elbow_joint' type='revolute'>
        <pose relative_to='shoulder'>0.000405 0.058 0.278851 0 -0 0</pose>
        <parent>shoulder</parent>
        <child>elbow</child>
        <axis>
          <xyz>0 -1 0</xyz>
          <limit>
            <lower>-2.87979</lower>
            <upper>2.87979</upper>
            <effort>100</effort>
            <velocity>100</velocity>
          </limit>
          <dynamics>
            <spring_reference>0</spring_reference>
            <spring_stiffness>0</spring_stiffness>
          </dynamics>
        </axis>
      </joint>
      <link name='elbow'>
        <pose relative_to='elbow_joint'>0 0 0 0 -0 0</pose>
        <inertial>
          <pose>-0.000337 -0.027977 0.079133 0 -0 0</pose>
          <mass>2.36516</mass>
          <inertia>
            <ixx>0.012144</ixx>
            <ixy>-2e-06</ixy>
            <ixz>8.9e-05</ixz>
            <iyy>0.012502</iyy>
            <iyz>-4e-06</iyz>
            <izz>0.001475</izz>
          </inertia>
        </inertial>
        <collision name='elbow_collision'>
          <pose>0.004596 -0.028 -0.453478 0 -0 0</pose>
          <geometry>
            <mesh>
              <scale>0.001 0.001 0.001</scale>
              <uri>/home/jc/flipkartGrid_ws/src/flipkartGrid/ajgar_description/meshes/elbow.stl</uri>
            </mesh>
          </geometry>
          <surface>
            <contact>
              <ode/>
            </contact>
            <friction>
              <ode>
                <mu>0.2</mu>
                <mu2>0.2</mu2>
              </ode>
              <torsional>
                <ode/>
              </torsional>
            </friction>
            <bounce/>
          </surface>
          <max_contacts>10</max_contacts>
        </collision>
        <visual name='elbow_visual'>
          <pose>0.004596 -0.028 -0.453478 0 -0 0</pose>
          <geometry>
            <mesh>
              <scale>0.001 0.001 0.001</scale>
              <uri>/home/jc/flipkartGrid_ws/src/flipkartGrid/ajgar_description/meshes/elbow.stl</uri>
            </mesh>
          </geometry>
          <material>
            <script>
              <name>Gazebo/Silver</name>
              <uri>file://media/materials/scripts/gazebo.material</uri>
            </script>
          </material>
        </visual>
        <self_collide>1</self_collide>
        <enable_wind>0</enable_wind>
        <kinematic>0</kinematic>
      </link>
      <joint name='lower_wrist_joint' type='revolute'>
        <pose relative_to='elbow'>0 -0.028 0.2 0 -0 0</pose>
        <parent>elbow</parent>
        <child>wrist</child>
        <axis>
          <xyz>0 0 1</xyz>
          <limit>
            <lower>-2.87979</lower>
            <upper>2.87979</upper>
            <effort>100</effort>
            <velocity>100</velocity>
          </limit>
          <dynamics>
            <spring_reference>0</spring_reference>
            <spring_stiffness>0</spring_stiffness>
          </dynamics>
        </axis>
      </joint>
      <link name='wrist'>
        <pose relative_to='lower_wrist_joint'>0 0 0 0 -0 0</pose>
        <inertial>
          <pose>0.008311 -0.010419 0.025505 0 -0 0</pose>
          <mass>0.338076</mass>
          <inertia>
            <ixx>0.000584</ixx>
            <ixy>8.6e-05</ixy>
            <ixz>-5.5e-05</ixz>
            <iyy>0.00026</iyy>
            <iyz>7e-05</iyz>
            <izz>0.000535</izz>
          </inertia>
        </inertial>
        <collision name='wrist_collision'>
          <pose>0.004596 0 -0.653478 0 -0 0</pose>
          <geometry>
            <mesh>
              <scale>0.001 0.001 0.001</scale>
              <uri>/home/jc/flipkartGrid_ws/src/flipkartGrid/ajgar_description/meshes/wrist.stl</uri>
            </mesh>
          </geometry>
          <surface>
            <contact>
              <ode/>
            </contact>
            <friction>
              <ode>
                <mu>0.2</mu>
                <mu2>0.2</mu2>
              </ode>
              <torsional>
                <ode/>
              </torsional>
            </friction>
            <bounce/>
          </surface>
          <max_contacts>10</max_contacts>
        </collision>
        <visual name='wrist_visual'>
          <pose>0.004596 0 -0.653478 0 -0 0</pose>
          <geometry>
            <mesh>
              <scale>0.001 0.001 0.001</scale>
              <uri>/home/jc/flipkartGrid_ws/src/flipkartGrid/ajgar_description/meshes/wrist.stl</uri>
            </mesh>
          </geometry>
          <material>
            <script>
              <name>Gazebo/Silver</name>
              <uri>file://media/materials/scripts/gazebo.material</uri>
            </script>
          </material>
        </visual>
        <self_collide>1</self_collide>
        <enable_wind>0</enable_wind>
        <kinematic>0</kinematic>
      </link>
      <joint name='upper_wrist_joint' type='revolute'>
        <pose relative_to='wrist'>0 -0.037 0.045 0 -0 0</pose>
        <parent>wrist</parent>
        <child>suction</child>
        <axis>
          <xyz>0 1 0</xyz>
          <limit>
            <lower>-2.87979</lower>
            <upper>2.87979</upper>
            <effort>100</effort>
            <velocity>100</velocity>
          </limit>
          <dynamics>
            <spring_reference>0</spring_reference>
            <spring_stiffness>0</spring_stiffness>
          </dynamics>
        </axis>
      </joint>
      <link name='suction'>
        <pose relative_to='upper_wrist_joint'>0 0 0 0 -0 0</pose>
        <inertial>
          <pose>-8.5e-05 0.03652 8.9e-05 0 -0 0</pose>
          <mass>0.605325</mass>
          <inertia>
            <ixx>0.000476</ixx>
            <ixy>0</ixy>
            <ixz>1.7e-05</ixz>
            <iyy>0.000398</iyy>
            <iyz>0</iyz>
            <izz>0.000554</izz>
          </inertia>
        </inertial>
        <collision name='suction_collision'>
          <pose>0.004596 0.037 -0.698478 0 -0 0</pose>
          <geometry>
            <mesh>
              <scale>0.001 0.001 0.001</scale>
              <uri>/home/jc/flipkartGrid_ws/src/flipkartGrid/ajgar_description/meshes/suction.stl</uri>
            </mesh>
          </geometry>
          <surface>
            <contact>
              <ode/>
            </contact>
            <friction>
              <ode>
                <mu>0.2</mu>
                <mu2>0.2</mu2>
              </ode>
              <torsional>
                <ode/>
              </torsional>
            </friction>
            <bounce/>
          </surface>
          <max_contacts>10</max_contacts>
        </collision>
        <visual name='suction_visual'>
          <pose>0.004596 0.037 -0.698478 0 -0 0</pose>
          <geometry>
            <mesh>
              <scale>0.001 0.001 0.001</scale>
              <uri>/home/jc/flipkartGrid_ws/src/flipkartGrid/ajgar_description/meshes/suction.stl</uri>
            </mesh>
          </geometry>
          <material>
            <script>
              <name>Gazebo/Silver</name>
              <uri>file://media/materials/scripts/gazebo.material</uri>
            </script>
          </material>
        </visual>
        <self_collide>1</self_collide>
        <enable_wind>0</enable_wind>
        <kinematic>0</kinematic>
      </link>
      <joint name='end_joint' type='revolute'>
        <pose relative_to='suction'>0 0.037 0.0245 0 -0 0</pose>
        <parent>suction</parent>
        <child>end</child>
        <axis>
          <xyz>0 0 -1</xyz>
          <limit>
            <lower>-2.87979</lower>
            <upper>2.87979</upper>
            <effort>100</effort>
            <velocity>100</velocity>
          </limit>
          <dynamics>
            <spring_reference>0</spring_reference>
            <spring_stiffness>0</spring_stiffness>
          </dynamics>
        </axis>
      </joint>
      <link name='end'>
        <pose relative_to='end_joint'>0 0 0 0 -0 0</pose>
        <inertial>
          <pose>-0 -0 0.005897 0 -0 0</pose>
          <mass>0.0764269</mass>
          <inertia>
            <ixx>7e-06</ixx>
            <ixy>0</ixy>
            <ixz>0</ixz>
            <iyy>5e-06</iyy>
            <iyz>0</iyz>
            <izz>8e-06</izz>
          </inertia>
        </inertial>
        <collision name='end_collision'>
          <pose>0.004596 0 -0.722978 0 -0 0</pose>
          <geometry>
            <mesh>
              <scale>0.001 0.001 0.001</scale>
              <uri>/home/jc/flipkartGrid_ws/src/flipkartGrid/ajgar_description/meshes/end.stl</uri>
            </mesh>
          </geometry>
          <surface>
            <contact>
              <ode/>
            </contact>
            <friction>
              <ode>
                <mu>0.2</mu>
                <mu2>0.2</mu2>
              </ode>
              <torsional>
                <ode/>
              </torsional>
            </friction>
            <bounce/>
          </surface>
          <max_contacts>10</max_contacts>
        </collision>
        <visual name='end_visual'>
          <pose>0.004596 0 -0.722978 0 -0 0</pose>
          <geometry>
            <mesh>
              <scale>0.001 0.001 0.001</scale>
              <uri>/home/jc/flipkartGrid_ws/src/flipkartGrid/ajgar_description/meshes/end.stl</uri>
            </mesh>
          </geometry>
          <material>
            <script>
              <name>Gazebo/Silver</name>
              <uri>file://media/materials/scripts/gazebo.material</uri>
            </script>
          </material>
        </visual>
        <self_collide>1</self_collide>
        <enable_wind>0</enable_wind>
        <kinematic>0</kinematic>
      </link>
      <static>0</static>
      <plugin name='control' filename='libgazebo_ros_control.so'>
        <robotNamespace>/</robotNamespace>
      </plugin>
      <pose>0.65 0 0 0 -0 0</pose>
    </model>
  </world>
</sdf>
